Workbook

Sheet Сентябрь
A2: Предмет | B2: Фамилия Имя Отчество | C2: Оклад за полную ставку | D2: Ставка факт | E2: Тарифная ставка/Оклад | F2: Сентябрь | G2: Октябрь | H2: Ноябрь | I2: Декабрь | J2: Январь 2025 | K2: Февраль 2025 | L2: Март 2025 | M2: Апрель 2025 | N2: Май 2025 | O2: Июнь 2025
A4: Казахский язык и литература | B4: Абдыкадырова Айнур Рахманалыевна | D4: - | E4: 2700 | F4: =2*5 -> 10 | G4: 70 | H4: 50 | I4: 60
A5: Русский язык/Русская литература | B5: Утюпова Рабига Даулбаевна | D5: - | E5: 2700 | F5: 4 | G5: 126 | H5: 40
A6: Казахский язык и литература | B6: Омарова Жупаргуль Салыковна | D6: - | E6: 2 700 | F6: - | G6: - | H6: - | I6: - | J6: 40 | K6: 50 | L6: 50 | M6: 80 | N6: 60 | O6: 50
A7: Русская литература | B7: Бегалиева Светлана Турановна | D7: - | E7: 2 700 | F7: - | G7: - | H7: 60 | I7: 70 | J7: 50 | K7: 60 | L7: 70 | M7: 90 | N7: 50 | O7: -
A8: Русский язык | B8: Капсаламова Динара Мусатаевна | D8: - | E8: 2 700 | F8: - | G8: - | H8: - | I8: - | J8: 20 | K8: 60 | L8: 70 | M8: 70 | N8: 70 | O8: 50
A9: Иностранный язык | B9: Калиева Зухра Абдумижитовна | D9: - | E9: 2700 | F9: 82 | G9: 44 | H9: 40 | I9: 34 | J9: 50 | K9: 60 | L9: 66 | M9: 52 | N9: 52 | O9: -
A10: Математика | B10: Мұхамедова Әйгерім Әділжанқызы | D10: - | E10: 2700 | F10: - | G10: 42 | H10: 64 | I10: 80 | J10: 30 | K10: - | L10: 46 | M10: 74 | N10: 40 | O10: 52
A11: Математика/Физика | B11: Сүлейменова Фейруза Нұрғалиқызы | D11: - | E11: 2700 | F11: 80 | G11: 168 | H11: 44
A12: Физика | B12: Саудабаева Шаин Кошкенбаевна | D12: - | E12: 2 700 | F12: - | G12: - | H12: 40 | I12: 50 | J12: 30 | K12: 80 | L12: 78 | M12: 82 | N12: 48 | O12: 52
A13: Начальная военная и технологическая подготовка (+полевые сборы -30 ч) | B13: Тохчуков Тимур Казбекович | D13: - | E13: 2700 | F13: 76 | G13: 44 | H13: 40 | I13: 40 | J13: 30 | K13: 40 | L13: 42 | M13: 68 | N13: 100 | O13: -
A14: Химия | B14: Наренова Сауле Маратовна | D14: - | E14: 2700 | F14: 40 | G14: 50 | H14: -
A15: Химия | B15: Әлайдар Әли Мұратұлы | D15: - | E15: 2 700 | F15: - | G15: - | H15: 40 | I15: 40 | J15: 10
A16: Химия/Биология | B16: Жартенова Акмарал Бахытовна | D16: - | E16: 2700 | F16: 130 | G16: 140 | H16: 120 | I16: 140 | J16: 60 | K16: 90 | L16: 90 | M16: 140 | N16: 70 | O16: -
A17: Графика и проектирование | B17: Светенко Мария Сергеевна | D17: - | E17: 2 700 | F17: - | G17: - | H17: - | I17: - | J17: 30 | K17: - | L17: 12 | M17: 50 | N17: 108 | O17: -
A18: Применение базовых знаний экономики и основ предпринимательства / Структура отрасли/ Менеджмент в профессиональной деятельности | B18: Светенко Мария Сергеевна | D18: - | E18: 2700 | F18: 30 | G18: 24 | H18: 32 | I18: 20
A19: Информатика | B19: Назарова Эльмира Бауыржановна | D19: - | E19: 2 700 | F19: - | G19: - | H19: - | I19: - | J19: 30 | K19: 40 | L19: 40 | M19: 50 | N19: - | O19: -
A20: Применение основ социальных наук для социализации и адаптации в обществе и трудовом коллективе | B20: Нугуманова Нургул Абдуллаевна | D20: - | E20: 2700 | F20: - | G20: 26 | H20: 50 | I20: 66 | J20: 12 | K20: 16 | L20: 12 | M20: 16 | N20: 12 | O20: -
A21: Применение основ социальных наук для социализации и адаптации в обществе и трудовом коллективе | B21: Жампетова Айгерим Оралбековна | D21: - | E21: 2 700 | F21: - | G21: 30 | H21: 62 | I21: 34 | J21: - | K21: - | L21: - | M21: - | N21: - | O21: -
A22: Всемирная история/Глобальные компетенции | B22: Рыбакова Лидия Владимировна | D22: - | E22: 2700 | F22: 116 | G22: 104 | H22: 130 | I22: 130 | J22: 60 | K22: 80 | L22: 80 | M22: 90 | N22: 50 | O22: 52
A23: Развитие и совершенствование физических качеств/ Физическая культура | B23: Асқарова Айза Ерболқызы | E23: 2700 | F23: 104 | G23: 100 | H23: 126 | I23: 105 | J23: 42 | K23: 56 | L23: 56 | M23: 60 | N23: 48 | O23: -
A24: Преподаватель организатор по НВП | B24: Тохчуков Тимур Казбекович | C24: 250000 | D24: 0.2 | E24: =C24*D24 -> 50000
A25: Преподаватель профильных дисциплин | B25: Бенли Рустем Артурович | C25: 385542 | D25: 2.49 | E25: =C25*D25 -> 959999.58
A26: Преподаватель профильных дисциплин | B26: Троянов Даниил Дмитриевич | C26: 377352 | D26: 2.53 | E26: =C26*D26 -> 954700.56
A27: Психолог | B27: Бектемирова Гульжанат Абулгалиевна | C27: 200 000 | D27: 0.2 | E27: 40000 | F27: УВОЛЕНА
A28: Педагог-психолог | B28: Светенко Мария Сергеевна | C28: 200 000 | D28: 0.2 | E28: 40 000
G29: 4618300
A31: Каждого 10-го числа оплата у | B31: Яхьянова Зухрагуль Магаметжановна

Sheet На 2025 год
A1: Предмет | B1: Фамилия Имя Отчество | C1: Оклад за полную ставку | D1: Ставка факт | E1: Тарифная ставка / Оклад | F1: Часов по РУП за семестр | G1: Сумма | H1: Январь | J1: Февраль | L1: Март | N1: Апрель | P1: Май | R1: Июнь | T1: Июль | V1: Август | X1: Часов по РУП за семестр | Y1: Сентябрь | AA1: Октябрь | AC1: Ноябрь | AE1: Декабрь
H2: Часы | I2: сумма | J2: Часы | K2: сумма | L2: Часы | M2: сумма | N2: Часы | O2: сумма | P2: Часы | Q2: сумма | R2: Часы | S2: сумма | T2: Часы | U2: сумма | V2: Часы | W2: сумма | Y2: Часы | Z2: сумма | AA2: Часы | AB2: сумма | AC2: Часы | AD2: сумма | AE2: Часы | AF2: сумма
A3: Казахский язык и литература | B3: Абдыкадырова Айнур Рахманалыевна | D3: - | E3: 2700 | F3: 56 | G3: =H3+J3+L3+N3+P3+R3 -> 56 | H3: 8 | I3: =2700*(H3*5) -> 108000 | J3: 12 | K3: =2700*(J3*5) -> 162000 | L3: 10 | M3: =2700*(L3*5) -> 135000 | N3: 8 | O3: =2700*(N3*5) -> 108000 | P3: 14 | Q3: =2700*(P3*5) -> 189000 | R3: 4 | S3: =2700*(R3*5) -> 54000 | U3: =2700*(T3*5) -> 0 | W3: =2700*(V3*5) -> 0 | X3: 40 | Y3: 10 | Z3: =2700*(Y3*10) -> 270000 | AA3: 10 | AB3: =2700*(AA3*10) -> 270000 | AC3: 10 | AD3: =2700*(AC3*10) -> 270000 | AE3: 10 | AF3: =2700*(AE3*10) -> 270000
A4: Русский язык | B4: Бегалиева Светлана Турановна | D4: - | E4: 2 700 | F4: 56 | G4: =H4+J4+L4+N4+P4+R4 -> 64 | H4: 10 | I4: =2700*(H4*5) -> 135000 | J4: 12 | K4: =2700*(J4*5) -> 162000 | L4: 12 | M4: =2700*(L4*5) -> 162000 | N4: 12 | O4: =2700*(N4*5) -> 162000 | P4: 12 | Q4: =2700*(P4*5) -> 162000 | R4: 6 | S4: =2700*(R4*5) -> 81000 | U4: =2700*(T4*5) -> 0 | W4: =2700*(V4*5) -> 0 | X4: 40 | Y4: 10 | Z4: =2700*(Y4*10) -> 270000 | AA4: 10 | AB4: =2700*(AA4*10) -> 270000 | AC4: 10 | AD4: =2700*(AC4*10) -> 270000 | AE4: 10 | AF4: =2700*(AE4*10) -> 270000
A5: Русская литература | B5: Бегалиева Светлана Турановна | E5: 2700 | F5: 56 | G5: =H5+J5+L5+N5+P5+R5 -> 68 | H5: 8 | I5: =2700*(H5*5) -> 108000 | J5: 12 | K5: =2700*(J5*5) -> 162000 | L5: 12 | M5: =2700*(L5*5) -> 162000 | N5: 16 | O5: =2700*(N5*5) -> 216000 | P5: 16 | Q5: =2700*(P5*5) -> 216000 | R5: 4 | S5: =2700*(R5*5) -> 54000 | U5: =2700*(T5*5) -> 0 | W5: =2700*(V5*5) -> 0 | X5: 40 | Y5: 10 | Z5: =2700*(Y5*10) -> 270000 | AA5: 10 | AB5: =2700*(AA5*10) -> 270000 | AC5: 10 | AD5: =2700*(AC5*10) -> 270000 | AE5: 10 | AF5: =2700*(AE5*10) -> 270000
A6: Иностранный язык | B6: Калиева Зухра Абдумижитовна | D6: - | E6: 2700 | F6: 56 | G6: =H6+J6+L6+N6+P6+R6 -> 56 | H6: 10 | I6: =2700*(H6*5) -> 135000 | J6: 12 | K6: =2700*(J6*5) -> 162000 | L6: 10 | M6: =2700*(L6*5) -> 135000 | N6: 10 | O6: =2700*(N6*5) -> 135000 | P6: 10 | Q6: =2700*(P6*5) -> 135000 | R6: 4 | S6: =2700*(R6*5) -> 54000 | U6: =2700*(T6*5) -> 0 | W6: =2700*(V6*5) -> 0 | X6: 40 | Y6: 10 | Z6: =2700*(Y6*10) -> 270000 | AA6: 10 | AB6: =2700*(AA6*10) -> 270000 | AC6: 10 | AD6: =2700*(AC6*10) -> 270000 | AE6: 10 | AF6: =2700*(AE6*10) -> 270000
A7: История Казахстана | B7: Рыбакова Лидия Владимировна | E7: 2700 | F7: 72 | G7: =H7+J7+L7+N7+P7+R7 -> 72 | H7: 12 | I7: =2700*(H7*5) -> 162000 | J7: 16 | K7: =2700*(J7*5) -> 216000 | L7: 16 | M7: =2700*(L7*5) -> 216000 | N7: 14 | O7: =2700*(N7*5) -> 189000 | P7: 10 | Q7: =2700*(P7*5) -> 135000 | R7: 4 | S7: =2700*(R7*5) -> 54000 | U7: =2700*(T7*5) -> 0 | W7: =2700*(V7*5) -> 0 | X7: 0 | Y7: 0 | Z7: =2700*(Y7*10) -> 0 | AA7: 0 | AB7: =2700*(AA7*10) -> 0 | AC7: 0 | AD7: =2700*(AC7*10) -> 0 | AE7: 0 | AF7: =2700*(AE7*10) -> 0
A8: Математика | B8: Мұхамедова Әйгерім Әділжанқызы | D8: - | E8: 2700 | F8: 40 | G8: =H8+J8+L8+N8+P8+R8 -> 46 | H8: 6 | I8: =2700*(H8*5) -> 81000 | J8: 8 | K8: =2700*(J8*5) -> 108000 | L8: 8 | M8: =2700*(L8*5) -> 108000 | N8: 8 | O8: =2700*(N8*5) -> 108000 | P8: 12 | Q8: =2700*(P8*5) -> 162000 | R8: 4 | S8: =2700*(R8*5) -> 54000 | U8: =2700*(T8*5) -> 0 | W8: =2700*(V8*5) -> 0 | X8: 40 | Y8: 10 | Z8: =2700*(Y8*10) -> 270000 | AA8: 10 | AB8: =2700*(AA8*10) -> 270000 | AC8: 10 | AD8: =2700*(AC8*10) -> 270000 | AE8: 10 | AF8: =2700*(AE8*10) -> 270000
A9: Информатика | E9: 2700 | F9: 32 | G9: =H9+J9+L9+N9+P9+R9 -> 32 | H9: 6 | I9: =2700*(H9*5) -> 81000 | J9: 8 | K9: =2700*(J9*5) -> 108000 | L9: 8 | M9: =2700*(L9*5) -> 108000 | N9: 8 | O9: =2700*(N9*5) -> 108000 | P9: 2 | Q9: =2700*(P9*5) -> 27000 | R9: 0 | S9: =2700*(R9*5) -> 0 | U9: =2700*(T9*5) -> 0 | W9: =2700*(V9*5) -> 0 | X9: 32 | Y9: 8 | Z9: =2700*(Y9*10) -> 216000 | AA9: 8 | AB9: =2700*(AA9*10) -> 216000 | AC9: 8 | AD9: =2700*(AC9*10) -> 216000 | AE9: 8 | AF9: =2700*(AE9*10) -> 216000
A10: Начальная военная и технологическая подготовка (+полевые сборы -30 ч) | B10: Тохчуков Тимур Казбекович | E10: 2700 | F10: 56 | G10: =H10+J10+L10+N10+P10+R10 -> 56 | H10: 6 | I10: =2700*(H10*5) -> 81000 | J10: 8 | K10: =2700*(J10*5) -> 108000 | L10: 12 | M10: =2700*(L10*5) -> 162000 | N10: 8 | O10: =2700*(N10*5) -> 108000 | P10: 14 | Q10: =2700*(P10*5) -> 189000 | R10: 8 | S10: =2700*(R10*5) -> 108000 | U10: =2700*(T10*5) -> 0 | W10: =2700*(V10*5) -> 0 | X10: 40 | Y10: 10 | Z10: =2700*(Y10*10) -> 270000 | AA10: 10 | AB10: =2700*(AA10*10) -> 270000 | AC10: 10 | AD10: =2700*(AC10*10) -> 270000 | AE10: 10 | AF10: =2700*(AE10*10) -> 270000
A11: Физическая культура | B11: Асқарова Айза Ерболқызы | E11: 2700 | F11: 40 | G11: =H11+J11+L11+N11+P11+R11 -> 40 | H11: 6 | I11: =2700*(H11*5) -> 81000 | J11: 8 | K11: =2700*(J11*5) -> 108000 | L11: 8 | M11: =2700*(L11*5) -> 108000 | N11: 8 | O11: =2700*(N11*5) -> 108000 | P11: 10 | Q11: =2700*(P11*5) -> 135000 | R11: 0 | S11: =2700*(R11*5) -> 0 | U11: =2700*(T11*5) -> 0 | W11: =2700*(V11*5) -> 0 | X11: 40 | Y11: 10 | Z11: =2700*(Y11*10) -> 270000 | AA11: 10 | AB11: =2700*(AA11*10) -> 270000 | AC11: 10 | AD11: =2700*(AC11*10) -> 270000 | AE11: 10 | AF11: =2700*(AE11*10) -> 270000
A12: Физика | B12: Саудабаева Шаин Кошкенбаевна | D12: - | E12: 2 700 | F12: 56 | G12: =H12+J12+L12+N12+P12+R12 -> 56 | H12: 6 | I12: =2700*(H12*5) -> 81000 | J12: 8 | K12: =2700*(J12*5) -> 108000 | L12: 12 | M12: =2700*(L12*5) -> 162000 | N12: 8 | O12: =2700*(N12*5) -> 108000 | P12: 14 | Q12: =2700*(P12*5) -> 189000 | R12: 8 | S12: =2700*(R12*5) -> 108000 | U12: =2700*(T12*5) -> 0 | W12: =2700*(V12*5) -> 0 | X12: 40 | Y12: 10 | Z12: =2700*(Y12*10) -> 270000 | AA12: 10 | AB12: =2700*(AA12*10) -> 270000 | AC12: 10 | AD12: =2700*(AC12*10) -> 270000 | AE12: 10 | AF12: =2700*(AE12*10) -> 270000
A13: Химия | B13: Әлайдар Әли Мұратұлы | D13: - | E13: 2700 | F13: 56 | G13: =H13+J13+L13+N13+P13+R13 -> 62 | H13: 6 | I13: =2700*(H13*5) -> 81000 | J13: 14 | K13: =2700*(J13*5) -> 189000 | L13: 8 | M13: =2700*(L13*5) -> 108000 | N13: 8 | O13: =2700*(N13*5) -> 108000 | P13: 16 | Q13: =2700*(P13*5) -> 216000 | R13: 10 | S13: =2700*(R13*5) -> 135000 | U13: =2700*(T13*5) -> 0 | W13: =2700*(V13*5) -> 0 | X13: 40 | Y13: 10 | Z13: =2700*(Y13*10) -> 270000 | AA13: 10 | AB13: =2700*(AA13*10) -> 270000 | AC13: 10 | AD13: =2700*(AC13*10) -> 270000 | AE13: 10 | AF13: =2700*(AE13*10) -> 270000
A14: География | B14: Жартенова Акмарал Бахытовна | D14: - | E14: 2700 | G14: =H14+J14+L14+N14+P14+R14 -> 0 | H14: 0 | I14: =2700*(H14*5) -> 0 | J14: 0 | K14: =2700*(J14*5) -> 0 | L14: 0 | M14: =2700*(L14*5) -> 0 | N14: 0 | O14: =2700*(N14*5) -> 0 | P14: 0 | Q14: =2700*(P14*5) -> 0 | R14: 0 | S14: =2700*(R14*5) -> 0 | U14: =2700*(T14*5) -> 0 | W14: =2700*(V14*5) -> 0 | X14: 72 | Y14: 18 | Z14: =2700*(Y14*10) -> 486000 | AA14: 18 | AB14: =2700*(AA14*10) -> 486000 | AC14: 18 | AD14: =2700*(AC14*10) -> 486000 | AE14: 18 | AF14: =2700*(AE14*10) -> 486000
A15: Биология | B15: Жартенова Акмарал Бахытовна | D15: - | E15: 2 700 | F15: 32 | G15: =H15+J15+L15+N15+P15+R15 -> 38 | H15: 6 | I15: =2700*(H15*5) -> 81000 | J15: 8 | K15: =2700*(J15*5) -> 108000 | L15: 8 | M15: =2700*(L15*5) -> 108000 | N15: 8 | O15: =2700*(N15*5) -> 108000 | P15: 6 | Q15: =2700*(P15*5) -> 81000 | R15: 2 | S15: =2700*(R15*5) -> 27000 | U15: =2700*(T15*5) -> 0 | W15: =2700*(V15*5) -> 0 | X15: 32 | Y15: 8 | Z15: =2700*(Y15*10) -> 216000 | AA15: 8 | AB15: =2700*(AA15*10) -> 216000 | AC15: 8 | AD15: =2700*(AC15*10) -> 216000 | AE15: 8 | AF15: =2700*(AE15*10) -> 216000
A16: Всемирная история | B16: Рыбакова Лидия Владимировна | E16: 2700 | F16: 0 | G16: =H16+J16+L16+N16+P16+R16 -> 0 | I16: =2700*(H16*5) -> 0 | K16: =2700*(J16*5) -> 0 | M16: =2700*(L16*5) -> 0 | O16: =2700*(N16*5) -> 0 | Q16: =2700*(P16*5) -> 0 | S16: =2700*(R16*5) -> 0 | U16: =2700*(T16*5) -> 0 | W16: =2700*(V16*5) -> 0 | X16: 72 | Y16: 18 | Z16: =2700*(Y16*10) -> 486000 | AA16: 18 | AB16: =2700*(AA16*10) -> 486000 | AC16: 18 | AD16: =2700*(AC16*10) -> 486000 | AE16: 18 | AF16: =2700*(AE16*10) -> 486000
A17: Курс "Глобальные компетенции" | E17: 2700 | F17: 0 | G17: =H17+J17+L17+N17+P17+R17 -> 0 | I17: =2700*(H17*5) -> 0 | K17: =2700*(J17*5) -> 0 | M17: =2700*(L17*5) -> 0 | O17: =2700*(N17*5) -> 0 | Q17: =2700*(P17*5) -> 0 | S17: =2700*(R17*5) -> 0 | U17: =2700*(T17*5) -> 0 | W17: =2700*(V17*5) -> 0 | X17: 24 | Y17: 6 | Z17: =2700*(Y17*10) -> 162000 | AA17: 6 | AB17: =2700*(AA17*10) -> 162000 | AC17: 6 | AD17: =2700*(AC17*10) -> 162000 | AE17: 6 | AF17: =2700*(AE17*10) -> 162000
A18: Графика и проектирование \ Индивидуальный проект | E18: 2700 | F18: 40 | G18: =H18+J18+L18+N18+P18+R18 -> 40 | H18: 6 | I18: =2700*(H18*5) -> 81000 | J18: 0 | K18: =2700*(J18*5) -> 0 | L18: 4 | M18: =2700*(L18*5) -> 54000 | N18: 10 | O18: =2700*(N18*5) -> 135000 | P18: 14 | Q18: =2700*(P18*5) -> 189000 | R18: 6 | S18: =2700*(R18*5) -> 81000 | U18: =2700*(T18*5) -> 0 | W18: =2700*(V18*5) -> 0 | X18: 32 | Y18: 8 | Z18: =2700*(Y18*10) -> 216000 | AA18: 8 | AB18: =2700*(AA18*10) -> 216000 | AC18: 8 | AD18: =2700*(AC18*10) -> 216000 | AE18: 8 | AF18: =2700*(AE18*10) -> 216000
A19: Промежуточная аттестация | F19: 72 | G19: =H19+J19+L19+N19+P19+R19 -> 72 | I19: =2700*(H19*5) -> 0 | K19: =2700*(J19*5) -> 0 | M19: =2700*(L19*5) -> 0 | O19: =2700*(N19*5) -> 0 | Q19: =2700*(P19*5) -> 0 | R19: 72 | S19: =2700*(R19*5) -> 972000 | T19: 0 | U19: =2700*(T19*5) -> 0 | W19: =2700*(V19*5) -> 0 | X19: 0 | Z19: =2700*(Y19*10) -> 0 | AB19: =2700*(AA19*10) -> 0 | AD19: =2700*(AC19*10) -> 0 | AF19: =2700*(AE19*10) -> 0
F20: 720 | G20: =SUM(G3:G19) -> 758 | H20: =SUM(H3:H19) -> 96 | I20: =SUM(I3:I19) -> 1296000 | J20: =SUM(J3:J19) -> 126 | K20: =SUM(K3:K19) -> 1701000 | L20: =SUM(L3:L19) -> 128 | M20: =SUM(M3:M19) -> 1728000 | N20: =SUM(N3:N19) -> 126 | ... AF20: =SUM(AF3:AF19) -> 4212000
A21: Развитие и совершенствование физических качеств/ | B21: Асқарова Айза Ерболқызы | E21: 2700 | F21: 46 | G21: =H21+J21+L21+N21+P21+R21 -> 46 | H21: 6 | I21: =2700*(H21*3) -> 48600 | J21: 8 | K21: =2700*(J21*3) -> 64800 | L21: 8 | M21: =2700*(L21*3) -> 64800 | N21: 8 | O21: =2700*(N21*3) -> 64800 | P21: 10 | Q21: =2700*(P21*3) -> 81000 | R21: 6 | S21: =2700*(R21*3) -> 48600 | U21: =2700*(T21*3) -> 0 | W21: =2700*(V21*3) -> 0 | X21: 48 | Y21: 12 | Z21: =2700*(Y21*5) -> 162000 | AA21: 12 | AB21: =2700*(AA21*5) -> 162000 | AC21: 12 | AD21: =2700*(AC21*5) -> 162000 | AE21: 12 | AF21: =2700*(AE21*5) -> 162000
A22: Применение информационно-коммуникационных и цифровых технологий (ИКТ) / | D22: - | E22: 2 700 | F22: 0 | G22: =H22+J22+L22+N22+P22+R22 -> 0 | H22: 0 | I22: =2700*(H22*3) -> 0 | J22: 0 | K22: =2700*(J22*3) -> 0 | L22: 0 | M22: =2700*(L22*3) -> 0 | N22: 0 | O22: =2700*(N22*3) -> 0 | P22: 0 | Q22: =2700*(P22*3) -> 0 | R22: 0 | S22: =2700*(R22*3) -> 0 | U22: =2700*(T22*3) -> 0 | W22: =2700*(V22*3) -> 0 | X22: 96 | Y22: 24 | Z22: =2700*(Y22*5) -> 324000 | AA22: 24 | AB22: =2700*(AA22*5) -> 324000 | AC22: 24 | AD22: =2700*(AC22*5) -> 324000 | AE22: 24 | AF22: =2700*(AE22*5) -> 324000
A23: Применение базовых знаний экономики и основ предпринимательства / Структура отрасли/ Менеджмент в профессиональной деятельности | D23: - | E23: 2700 | F23: 0 | G23: =H23+J23+L23+N23+P23+R23 -> 0 | H23: 0 | I23: =2700*(H23*3) -> 0 | J23: 0 | K23: =2700*(J23*3) -> 0 | L23: 0 | M23: =2700*(L23*3) -> 0 | N23: 0 | O23: =2700*(N23*3) -> 0 | P23: 0 | Q23: =2700*(P23*3) -> 0 | R23: 0 | S23: =2700*(R23*3) -> 0 | U23: =2700*(T23*3) -> 0 | W23: =2700*(V23*3) -> 0 | X23: 48 | Y23: 12 | Z23: =2700*(Y23*5) -> 162000 | AA23: 12 | AB23: =2700*(AA23*5) -> 162000 | AC23: 12 | AD23: =2700*(AC23*5) -> 162000 | AE23: 12 | AF23: =2700*(AE23*5) -> 162000
A24: Применение основ социальных наук для социализации и адаптации в обществе и трудовом коллективе | B24: Нугуманова Нургул Абдуллаевна | D24: - | E24: 2700 | F24: 24 | G24: =H24+J24+L24+N24+P24+R24 -> 34 | H24: 6 | I24: =2700*(H24*3) -> 48600 | J24: 8 | K24: =2700*(J24*3) -> 64800 | L24: 8 | M24: =2700*(L24*3) -> 64800 | N24: 8 | O24: =2700*(N24*3) -> 64800 | P24: 4 | Q24: =2700*(P24*3) -> 32400 | R24: 0 | S24: =2700*(R24*3) -> 0 | U24: =2700*(T24*3) -> 0 | W24: =2700*(V24*3) -> 0 | X24: 144 | Y24: 36 | Z24: =2700*(Y24*5) -> 486000 | AA24: 36 | AB24: =2700*(AA24*5) -> 486000 | AC24: 36 | AD24: =2700*(AC24*5) -> 486000 | AE24: 36 | AF24: =2700*(AE24*5) -> 486000
A25: Промежуточная аттестация | F25: 0 | G25: =H25+J25+L25+N25+P25+R25 -> 0 | I25: =2700*(H25*3) -> 0 | K25: =2700*(J25*3) -> 0 | M25: =2700*(L25*3) -> 0 | O25: =2700*(N25*3) -> 0 | Q25: =2700*(P25*3) -> 0 | R25: 0 | S25: =2700*(R25*3) -> 0 | U25: =2700*(T25*3) -> 0 | W25: =2700*(V25*3) -> 0 | Z25: =2700*(Y25*5) -> 0 | AB25: =2700*(AA25*5) -> 0 | AD25: =2700*(AC25*5) -> 0 | AF25: =2700*(AE25*5) -> 0
A26: Итого за ООМ | F26: =SUM(F21:F25) -> 70 | G26: =SUM(G21:G25) -> 80 | H26: =SUM(H21:H25) -> 12 | I26: =SUM(I21:I25) -> 97200 | J26: =SUM(J21:J25) -> 16 | K26: =SUM(K21:K25) -> 129600 | L26: =SUM(L21:L25) -> 16 | M26: =SUM(M21:M25) -> 129600 | ... W26: =SUM(W21:W25) -> 0 | Y26: =SUM(Y21:Y25) -> 84 | Z26: =SUM(Z21:Z25) -> 1134000 | AA26: =SUM(AA21:AA25) -> 84 | AB26: =SUM(AB21:AB25) -> 1134000 | AC26: =SUM(AC21:AC25) -> 84 | AD26: =SUM(AD21:AD25) -> 1134000 | AE26: =SUM(AE21:AE25) -> 84 | AF26: =SUM(AF21:AF25) -> 1134000
B27: Бенли Рустем Артурович | C27: 385542 | D27: 2.49 | E27: =C27*D27 -> 959999.58 | I27: 959999.58 | K27: 959999.58 | M27: 959999.58 | O27: 959999.58 | Q27: 959999.58 | S27: 959999.58 | U27: 959999.58 | W27: 959999.58 | Z27: 959999.58 | AB27: 959999.58 | AD27: 959999.58 | AF27: 959999.58
B28: Троянов Даниил Дмитриевич | C28: 377352 | D28: 2.53 | E28: =C28*D28 -> 954700.56 | I28: 954700.56 | K28: 954700.56 | M28: 954700.56 | O28: 954700.56 | Q28: 954700.56 | S28: 954700.56 | U28: 954700.56 | W28: 954700.56 | Z28: 954700.56 | AB28: 954700.56 | AD28: 954700.56 | AF28: 954700.56
F29: 0 | G29: 24 | R29: 0 | S29: =2700*(R29*3) -> 0
C30: 350000 | D30: 2 | E30: =C30*D30 -> 700000 | Y30: 0 | Z30: 600000 | AA30: 0 | AB30: 600000 | AC30: 0 | AD30: 600000 | AE30: 0 | AF30: 600000
C31: 350000 | D31: 2 | E31: =C31*D31 -> 700000 | Y31: 0 | Z31: 600000 | AA31: 0 | AB31: 600000 | AC31: 0 | AD31: 600000 | AE31: 0 | AF31: 600000
C32: 350000 | D32: 2 | E32: =C32*D32 -> 700000 | Y32: 0 | Z32: 600000 | AA32: 0 | AB32: 600000 | AC32: 0 | AD32: 600000 | AE32: 0 | AF32: 600000
C33: 350000 | D33: 2 | E33: =C33*D33 -> 700000 | Y33: 0 | Z33: 600000 | AA33: 0 | AB33: 600000 | AC33: 0 | AD33: 600000 | AE33: 0 | AF33: 600000
C34: 350000 | D34: 2 | E34: =C34*D34 -> 700000 | Z34: 600000 | AB34: 600000 | AD34: 600000 | AF34: 600000
C35: 350000 | D35: 2 | E35: =C35*D35 -> 700000 | Z35: 600000 | AB35: 600000 | AD35: 600000 | AF35: 600000
A36: Итого за ПМ | F36: =SUM(F27:F29) -> 0 | G36: =SUM(G27:G29) -> 24 | H36: =SUM(H27:H29) -> 0 | I36: =SUM(I27:I29) -> 1914700.1 | J36: =SUM(J27:J29) -> 0 | K36: =SUM(K27:K29) -> 1914700.1 | L36: =SUM(L27:L29) -> 0 | M36: =SUM(M27:M29) -> 1914700.1 | ... W36: =SUM(W27:W29) -> 1914700.1 | Y36: =SUM(Y27:Y29) -> 0 | Z36: =SUM(Z27:Z35) -> 5514700.1 | AA36: =SUM(AA27:AA29) -> 0 | AB36: =SUM(AB27:AB35) -> 5514700.1 | AC36: =SUM(AC27:AC29) -> 0 | AD36: =SUM(AD27:AD35) -> 5514700.1 | AE36: =SUM(AE27:AE29) -> 0 | AF36: =SUM(AF27:AF35) -> 5514700.1
A37: Директор | B37: ДЖАЛИЛОВ АЗИЗ АВДУНОВИЧ | C37: 600000 | D37: 1 | E37: =C37*D37 -> 600000 | I37: 600000 | K37: 600000 | M37: 600000 | O37: 600000 | Q37: 600000 | S37: 600000 | U37: 600000 | W37: 600000 | Z37: 600000 | AB37: 600000 | AD37: 600000 | AF37: 600000
A38: Заместитель директора по воспитательной работе (забота о студентах) | B38: Мұхамедова Әйгерім Әдільжанқызы | C38: 350000 | D38: 1 | E38: =C38*D38 -> 350000 | I38: 350000 | K38: 350000 | M38: 350000 | O38: 350000 | Q38: 350000 | S38: 350000 | U38: 350000 | W38: 350000 | Z38: 350000 | AB38: 350000 | AD38: 350000 | AF38: 350000
A39: Заместитель директора по учебной работе и работе с контингентом | B39: Калиаскаров Данияр Айтахметович | C39: 450000 | D39: 1 | E39: =C39*D39 -> 450000 | I39: 450000 | K39: 450000 | M39: 450000 | O39: 450000 | Q39: 450000 | S39: 450000 | U39: 450000 | W39: 450000 | Z39: 450000 | AB39: 450000 | AD39: 450000 | AF39: 450000
A40: Заведующий хозяйством | B40: Тлемисов Жаксылык Бердикулович | C40: 300000 | D40: 0.5 | E40: =C40*D40 -> 150000 | I40: 150000 | K40: 150000 | M40: 150000 | O40: 150000 | Q40: 150000 | S40: 150000 | U40: 150000 | W40: 150000 | Z40: 150000 | AB40: 150000 | AD40: 150000 | AF40: 150000
...

Sheet Расчет ЗП для преподавателей на
R1: В шате | U1: По часовая
A2: Индекс | B2: Предмет | C2: Фамилия Имя Отчество | D2: Количество очных групп | E2: Количество заочных групп | F2: Всего часов на предмет очно | G2: Всего часов на предмет заочно | H2: Всего часов | I2: Ставка | J2: Количество преподавателей | K2: ставка | M2: часы учебной практики | N2: сумма оплаты | O2: часовой оплате | Q2: В месяц | R2: в месяц на каждого преподова | S2: В месяц | T2: Оклад за полную ставку | U2: в месяц на каждого преподова | V2: В месяц | W2: Всего за часы | X2: Оклад при по часовое оплате | AC2: Сентябрь | AE2: Октябрь | AG2: Ноябрь | AI2: Декабрь
Q3: =O3*X3 -> 0 | AC3: Часы | AD3: сумма | AE3: Часы | AF3: сумма | AG3: Часы | AH3: сумма | AI3: Часы | AJ3: сумма
A4: ООД 01 | B4: Казахский язык и литература | D4: 5 | F4: 96 | H4: =F4*D4 -> 480 | I4: =H4/720 -> 0.66666667 | J4: =I4 -> 0.66666667 | Q4: =O4*X4 -> 0 | S4: =I4*T4 -> 166666.67 | T4: 250000 | V4: =(H4/10)*X4 -> 129600 | W4: =H4*X4 -> 1296000 | X4: 2700 | Y4: 96 | Z4: =F4-Y4 -> 0
A5: ООД 02 | B5: Русский язык | D5: 5 | F5: 96 | H5: =F5*D5 -> 480 | I5: =H5/720 -> 0.66666667 | J5: =I5 -> 0.66666667 | Q5: =O5*X5 -> 0 | S5: =I5*T5 -> 166666.67 | T5: 250000 | V5: =(H5/10)*X5 -> 129600 | W5: =H5*X5 -> 1296000 | X5: 2700 | Y5: 96 | Z5: =F5-Y5 -> 0
A6: ООД 03 | B6: Русская литература | D6: 5 | F6: 96 | H6: =F6*D6 -> 480 | I6: =H6/720 -> 0.66666667 | J6: =I6 -> 0.66666667 | Q6: =O6*X6 -> 0 | S6: =I6*T6 -> 166666.67 | T6: 250000 | V6: =(H6/10)*X6 -> 129600 | W6: =H6*X6 -> 1296000 | X6: 2700 | Y6: 96 | Z6: =F6-Y6 -> 0
A7: ООД 04 | B7: Иностранный язык | D7: 5 | F7: 96 | H7: =F7*D7 -> 480 | I7: =H7/720 -> 0.66666667 | J7: =I7 -> 0.66666667 | S7: =I7*T7 -> 166666.67 | T7: 250000 | V7: =(H7/10)*X7 -> 129600 | W7: =H7*X7 -> 1296000 | X7: 2700 | Y7: 96 | Z7: =F7-Y7 -> 0
A8: ООД 05 | B8: История Казахстана | D8: 5 | F8: 72 | H8: =F8*D8 -> 360 | I8: =H8/720 -> 0.5 | J8: =I8 -> 0.5 | S8: =I8*T8 -> 125000 | T8: 250000 | V8: =(H8/10)*X8 -> 97200 | W8: =H8*X8 -> 972000 | X8: 2700 | Y8: 72 | Z8: =F8-Y8 -> 0
A9: ООД 06 | B9: Математика | D9: 5 | F9: 120 | H9: =F9*D9 -> 600 | I9: =H9/720 -> 0.83333333 | J9: =I9 -> 0.83333333 | S9: =I9*T9 -> 208333.33 | T9: 250000 | V9: =(H9/10)*X9 -> 162000 | W9: =H9*X9 -> 1620000 | X9: 2700 | Y9: 120 | Z9: =F9-Y9 -> 0
A10: ООД 07 | B10: Информатика | D10: 5 | F10: 72 | H10: =F10*D10 -> 360 | I10: =H10/720 -> 0.5 | J10: =I10 -> 0.5 | S10: =I10*T10 -> 125000 | T10: 250000 | V10: =(H10/10)*X10 -> 97200 | W10: =H10*X10 -> 972000 | X10: 2700 | Y10: 48 | Z10: =F10-Y10 -> 24
A11: ООД 08 | B11: Начальная военная и технологическая подготовка (+полевые сборы -30 ч) | D11: 2.5 | F11: 96 | H11: =F11*D11 -> 240 | I11: =H11/720 -> 0.33333333 | J11: =I11 -> 0.33333333 | S11: =I11*T11 -> 83333.333 | T11: 250000 | V11: =(H11/10)*X11 -> 96000 | W11: =H11*X11 -> 960000 | X11: 4000 | Y11: 96 | Z11: =F11-Y11 -> 0
A12: ООД 09 | B12: Физическая культура | D12: 2 | F12: 120 | H12: =F12*D12 -> 240 | I12: =H12/720 -> 0.33333333 | J12: =I12 -> 0.33333333 | S12: =I12*T12 -> 83333.333 | T12: 250000 | V12: =(H12/10)*X12 -> 96000 | W12: =H12*X12 -> 960000 | X12: 4000 | Y12: 120 | Z12: =F12-Y12 -> 0
A13: ООД 10 | B13: Физика | D13: 5 | F13: 96 | H13: =F13*D13 -> 480 | I13: =H13/720 -> 0.66666667 | J13: =I13 -> 0.66666667 | S13: =I13*T13 -> 166666.67 | T13: 250000 | V13: =(H13/10)*X13 -> 129600 | W13: =H13*X13 -> 1296000 | X13: 2700 | Y13: 96 | Z13: =F13-Y13 -> 0
A14: ООД 11 | B14: Химия | D14: 5 | F14: 96 | H14: =F14*D14 -> 480 | I14: =H14/720 -> 0.66666667 | J14: =I14 -> 0.66666667 | S14: =I14*T14 -> 166666.67 | T14: 250000 | V14: =(H14/10)*X14 -> 129600 | W14: =H14*X14 -> 1296000 | X14: 2700 | Y14: 96 | Z14: =F14-Y14 -> 0
A15: ООД 12 | B15: География | D15: 5 | F15: 72 | H15: =F15*D15 -> 360 | I15: =H15/720 -> 0.5 | J15: =I15 -> 0.5 | S15: =I15*T15 -> 125000 | T15: 250000 | V15: =(H15/10)*X15 -> 97200 | W15: =H15*X15 -> 972000 | X15: 2700 | Y15: 96 | Z15: =F15-Y15 -> -24
A16: ООД 13 | B16: Биология | D16: 2.5 | F16: 72 | H16: =F16*D16 -> 180 | I16: =H16/720 -> 0.25 | J16: =I16 -> 0.25 | S16: =I16*T16 -> 62500 | T16: 250000 | V16: =(H16/10)*X16 -> 72000 | W16: =H16*X16 -> 720000 | X16: 4000 | Y16: 72 | Z16: =F16-Y16 -> 0
A17: ООД 14 | B17: Всемирная история | D17: 5 | F17: 72 | H17: =F17*D17 -> 360 | I17: =H17/720 -> 0.5 | J17: =I17 -> 0.5 | S17: =I17*T17 -> 125000 | T17: 250000 | V17: =(H17/10)*X17 -> 97200 | W17: =H17*X17 -> 972000 | X17: 2700 | Y17: 96 | Z17: =F17-Y17 -> -24
A18: ООД 15 | B18: Курс "Глобальные компетенции" | D18: 2.5 | F18: 24 | H18: =F18*D18 -> 60 | I18: =H18/720 -> 0.083333333 | J18: =I18 -> 0.083333333 | S18: =I18*T18 -> 20833.333 | T18: 250000 | V18: =(H18/10)*X18 -> 24000 | W18: =H18*X18 -> 240000 | X18: 4000 | Y18: 24 | Z18: =F18-Y18 -> 0
A19: ООД 16 | B19: Графика и проектирование \ Индивидуальный проект | D19: 2.5 | F19: 72 | H19: =F19*D19 -> 180 | I19: =H19/720 -> 0.25 | J19: =I19 -> 0.25 | S19: =I19*T19 -> 62500 | T19: 250000 | V19: =(H19/10)*X19 -> 72000 | W19: =H19*X19 -> 720000 | X19: 4000 | Y19: 48 | Z19: =F19-Y19 -> 24
A20: ПА 01 | B20: Промежуточная аттестация | D20: 10 | F20: 72 | H20: =F20*D20 -> 720 | I20: =H20/720 -> 1 | J20: =I20 -> 1 | S20: =I20*T20 -> 250000 | T20: 250000 | V20: =(H20/10)*2700 -> 194400 | W20: =H20*X20 -> 1944000 | X20: 2700 | Y20: 72
B21: Итого ООД | H21: =F21*D21 -> 0 | I21: =H21/720 -> 0 | J21: =SUM(J4:J20) -> 9.0833333 | K21: =SUM(K4:K20) -> 0 | S21: =SUM(S4:S20) -> 2270833.3 | V21: =SUM(V4:V20) -> 1882800 | W21: =SUM(W4:W20) -> 18828000
A22: ООМ 1 | B22: Развитие и совершенствование физических качеств/ | D22: 2 | F22: 96 | G22: 29 | H22: =(F22*D22)+(G22*E22) -> 192 | I22: =H22/720 -> 0.26666667 | J22: =I22 -> 0.26666667 | S22: =I22*T22 -> 66666.667 | T22: 250000 | V22: =(H22/10)*X22 -> 76800 | W22: =H22*X22 -> 768000 | X22: 4000
A23: ООМ 2 | B23: Применение информационно-коммуникационных и цифровых технологий (ИКТ) / | D23: 3 | E23: 1 | F23: 96 | G23: 29 | H23: =(F23*D23)+(G23*E23) -> 317 | I23: =H23/720 -> 0.44027778 | J23: =I23 -> 0.44027778 | S23: =I23*T23 -> 110069.44 | T23: 250000 | V23: =(H23/10)*2700 -> 85590 | W23: =H23*X23 -> 1268000 | X23: 4000
A24: ООМ 3 | B24: Применение базовых знаний экономики и основ предпринимательства / Структура отрасли/ Менеджмент в профессиональной деятельности | D24: 3 | E24: 1 | F24: 48 | G24: 15 | H24: =(F24*D24)+(G24*E24) -> 159 | I24: =H24/720 -> 0.22083333 | J24: =I24 -> 0.22083333 | S24: =I24*T24 -> 55208.333 | T24: 250000 | V24: =(H24/10)*2700 -> 42930 | W24: =H24*X24 -> 636000 | X24: 4000
A25: ООМ 4 | B25: Применение основ социальных наук для социализации и адаптации в обществе и трудовом коллективе | D25: 3 | E25: 1 | F25: 120 | G25: 51 | H25: =(F25*D25)+(G25*E25) -> 411 | I25: =H25/720 -> 0.57083333 | J25: =I25 -> 0.57083333 | S25: =I25*T25 -> 142708.33 | T25: 250000 | V25: =(H25/10)*2700 -> 110970 | W25: =H25*X25 -> 1644000 | X25: 4000
B26: Промежуточная аттестация | H26: =F26*D26 -> 0 | I26: =H26/720 -> 0 | S26: =I26*T26 -> 0
B27: Итого ООМ | H27: =F27*D27 -> 0 | I27: =H27/720 -> 0 | J27: =SUM(J22:J26) -> 1.4986111 | K27: =SUM(K22:K26) -> 0 | S27: =SUM(S22:S26) -> 374652.78 | V27: =SUM(V22:V26) -> 316290 | W27: =SUM(W22:W26) -> 4316000
A28: ПМ 1 | B28: Создание web-страниц, сайтов с применением web-технологий | D28: 6 | E28: 1 | F28: 168 | G28: 84 | H28: =(F28*D28)+(G28*E28) -> 1092 | I28: =H28/720 -> 1.5166667 | J28: =I28 -> 1.5166667 | L28: =I28*T28 -> 530833.33 | M28: 72 | N28: =M28*2700 -> 194400 | R28: =S28/J28 -> 350000 | S28: =I28*T28 -> 530833.33 | T28: 350000 | U28: =V28/J28 -> 194400 | V28: =(H28/10)*2700 -> 294840 | W28: =H28*X28 -> 2948400 | X28: 2700
A29: ПМ 2 | B29: Прикладное программирование | D29: 6 | E29: 1 | F29: 264 | G29: 216 | H29: =(F29*D29)+(G29*E29) -> 1800 | I29: =H29/720 -> 2.5 | J29: =I29 -> 2.5 | L29: =I29*T29 -> 875000 | M29: 96 | N29: =M29*2700 -> 259200 | R29: =S29/J29 -> 350000 | S29: =I29*T29 -> 875000 | T29: 350000 | U29: =V29/J29 -> 194400 | V29: =(H29/10)*2700 -> 486000 | W29: =H29*X29 -> 4860000 | X29: 2700
A30: ПМ 3 | B30: Разработка модулей программного обеспечения для компьютерных систем | D30: 3 | E30: 2 | F30: 336 | G30: 156 | H30: =(F30*D30)+(G30*E30) -> 1320 | I30: =H30/720 -> 1.8333333 | J30: =I30 -> 1.8333333 | L30: =I30*T30 -> 641666.67 | M30: 96 | N30: =M30*2700 -> 259200 | R30: =S30/J30 -> 350000 | S30: =I30*T30 -> 641666.67 | T30: 350000 | U30: =V30/J30 -> 194400 | V30: =(H30/10)*2700 -> 356400 | W30: =H30*X30 -> 3564000 | X30: 2700
A31: ПМ 4 | B31: Разработка браузерных приложений | D31: 3 | E31: 2 | F31: 360 | G31: 130 | H31: =(F31*D31)+(G31*E31) -> 1340 | I31: =H31/720 -> 1.8611111 | J31: =I31 -> 1.8611111 | L31: =I31*T31 -> 651388.89 | M31: 96 | N31: =M31*2700 -> 259200 | R31: =S31/J31 -> 350000 | S31: =I31*T31 -> 651388.89 | T31: 350000 | U31: =V31/J31 -> 194400 | V31: =(H31/10)*2700 -> 361800 | W31: =H31*X31 -> 3618000 | X31: 2700
A32: ПМ 5 | B32: Разработка веб приложений на React | D32: 3 | E32: 2 | F32: 264 | G32: 108 | H32: =(F32*D32)+(G32*E32) -> 1008 | I32: =H32/720 -> 1.4 | J32: =I32 -> 1.4 | L32: =I32*T32 -> 490000 | M32: 96 | N32: =M32*2700 -> 259200 | R32: =S32/J32 -> 350000 | S32: =I32*T32 -> 490000 | T32: 350000 | U32: =V32/J32 -> 194400 | V32: =(H32/10)*2700 -> 272160 | W32: =H32*X32 -> 2721600 | X32: 2700
A33: ПМ 6 | B33: Поддержка и тестирование программных модулей | D33: 3 | E33: 2 | F33: 144 | G33: 65 | H33: =(F33*D33)+(G33*E33) -> 562 | I33: =H33/720 -> 0.78055556 | J33: =I33 -> 0.78055556 | L33: =I33*T33 -> 273194.44 | M33: 96 | N33: =M33*2700 -> 259200 | R33: =S33/J33 -> 350000 | S33: =I33*T33 -> 273194.44 | T33: 350000 | U33: =V33/J33 -> 194400 | V33: =(H33/10)*2700 -> 151740 | W33: =H33*X33 -> 1517400 | X33: 2700
A34: ПМ 7 | B34: Сопровождение и обслуживание программного обеспечения компьютерных систем | D34: 1 | E34: 1 | F34: 144 | G34: 84 | H34: =(F34*D34)+(G34*E34) -> 228 | I34: =H34/720 -> 0.31666667 | J34: =I34 -> 0.31666667 | M34: 96 | N34: =M34*2700 -> 259200 | R34: =S34/J34 -> 350000 | S34: =I34*T34 -> 110833.33 | T34: 350000 | U34: =V34/J34 -> 194400 | V34: =(H34/10)*2700 -> 61560 | W34: =H34*X34 -> 615600 | X34: 2700
A35: ПМ 8 | B35: Разработка, администрирование и защита баз данных | D35: 1 | E35: 1 | F35: 144 | G35: 84 | H35: =(F35*D35)+(G35*E35) -> 228 | I35: =H35/720 -> 0.31666667 | J35: =I35 -> 0.31666667 | M35: 96 | N35: =M35*2700 -> 259200 | R35: =S35/J35 -> 350000 | S35: =I35*T35 -> 110833.33 | T35: 350000 | U35: =V35/J35 -> 194400 | V35: =(H35/10)*2700 -> 61560 | W35: =H35*X35 -> 615600 | X35: 2700
B36: Промежуточной аттестации (нед) | D36: 1 | E36: 1 | F36: 96 | G36: 44 | H36: =(F36*D36)+(G36*E36) -> 140 | I36: =H36/720 -> 0.19444444 | J36: =I36 -> 0.19444444 | R36: =S36/J36 -> 350000 | S36: =I36*T36 -> 68055.556 | T36: 350000 | U36: =V36/J36 -> 194400 | V36: =(H36/10)*2700 -> 37800 | W36: =H36*X36 -> 378000 | X36: 2700
B37: Итоговая аттестация | D37: 1 | E37: 1 | F37: 72 | G37: 22 | H37: =(F37*D37)+(G37*E37) -> 94 | I37: =H37/720 -> 0.13055556 | J37: =I37 -> 0.13055556 | R37: =S37/J37 -> 350000 | S37: =I37*T37 -> 45694.444 | T37: 350000 | U37: =V37/J37 -> 194400 | V37: =(H37/10)*2700 -> 25380 | W37: =H37*X37 -> 253800 | X37: 2700
B38: Итого ПМ | J38: =SUM(J28:J37) -> 10.85 | K38: =SUM(K28:K37) -> 0 | L38: =SUM(L28:L37) -> 3462083.3 | M38: =SUM(M28:M37) -> 744 | N38: =SUM(N28:N37) -> 2008800 | O38: =SUM(O28:O37) -> 0 | P38: =SUM(P28:P37) -> 0 | Q38: =SUM(Q28:Q37) -> 0 | ... S38: =SUM(S28:S37) -> 3797500 | U38: =SUM(U28:U37) -> 1944000 | V38: =SUM(V28:V37) -> 2109240 | W38: =SUM(W28:W37) -> 21092400
B39: Итого | J39: =J21+J27+J38 -> 21.431944 | S39: =S21+S27+S38 -> 6442986.1 | U39: =U21+U27+U38 -> 1944000 | V39: =V21+V27+V38 -> 4308330 | W39: =W21+W27+W38 -> 44236400
L41: =L38+Q38+V27+V21 -> 5661173.3 | S41: 76924212 | V41: 76924212
...

Sheet Расчет ЗП для препод. на 2025-2
R1: В шате | U1: По часовая
A2: Индекс | B2: Предмет | C2: Фамилия Имя Отчество | D2: Количество очных групп | E2: Количество заочных групп | F2: Всего часов на предмет очно | G2: Всего часов на предмет заочно | H2: Всего часов | I2: Ставка | J2: Количество преподавателей | K2: ставка | M2: часы учебной практики | N2: сумма оплаты | O2: часовой оплате | Q2: В месяц | R2: в месяц на каждого преподова | S2: В месяц | T2: Оклад за полную ставку | U2: в месяц на каждого преподова | V2: В месяц | W2: Всего за часы | X2: Оклад при по часовое оплате | AC2: Сентябрь | AE2: Октябрь | AG2: Ноябрь | AI2: Декабрь
Q3: =O3*X3 -> 0 | AC3: Часы | AD3: сумма | AE3: Часы | AF3: сумма | AG3: Часы | AH3: сумма | AI3: Часы | AJ3: сумма
A4: ООД 01 | B4: Казахский язык и литература | D4: 5 | F4: 110.4 | H4: =F4*D4 -> 552 | I4: =H4/720 -> 0.76666667 | J4: =I4 -> 0.76666667 | Q4: =O4*X4 -> 0 | S4: =I4*T4 -> 191666.67 | T4: 250000 | V4: =(H4/10)*X4 -> 149040 | W4: =H4*X4 -> 1490400 | X4: 2700 | Y4: 96 | Z4: =F4-Y4 -> 14.4
A5: ООД 02 | B5: Русский язык | D5: 5 | F5: 110.4 | H5: =F5*D5 -> 552 | I5: =H5/720 -> 0.76666667 | J5: =I5 -> 0.76666667 | Q5: =O5*X5 -> 0 | S5: =I5*T5 -> 191666.67 | T5: 250000 | V5: =(H5/10)*X5 -> 149040 | W5: =H5*X5 -> 1490400 | X5: 2700 | Y5: 96 | Z5: =F5-Y5 -> 14.4
A6: ООД 03 | B6: Русская литература | D6: 5 | F6: 96 | H6: =F6*D6 -> 480 | I6: =H6/720 -> 0.66666667 | J6: =I6 -> 0.66666667 | Q6: =O6*X6 -> 0 | S6: =I6*T6 -> 166666.67 | T6: 250000 | V6: =(H6/10)*X6 -> 129600 | W6: =H6*X6 -> 1296000 | X6: 2700 | Y6: 96 | Z6: =F6-Y6 -> 0
A7: ООД 04 | B7: Иностранный язык | D7: 5 | F7: 96 | H7: =F7*D7 -> 480 | I7: =H7/720 -> 0.66666667 | J7: =I7 -> 0.66666667 | S7: =I7*T7 -> 166666.67 | T7: 250000 | V7: =(H7/10)*X7 -> 129600 | W7: =H7*X7 -> 1296000 | X7: 2700 | Y7: 96 | Z7: =F7-Y7 -> 0
A8: ООД 05 | B8: История Казахстана | D8: 5 | F8: 110.4 | H8: =F8*D8 -> 552 | I8: =H8/720 -> 0.76666667 | J8: =I8 -> 0.76666667 | S8: =I8*T8 -> 191666.67 | T8: 250000 | V8: =(H8/10)*X8 -> 149040 | W8: =H8*X8 -> 1490400 | X8: 2700 | Y8: 72 | Z8: =F8-Y8 -> 38.4
A9: ООД 06 | B9: Математика | D9: 5 | F9: 110.4 | H9: =F9*D9 -> 552 | I9: =H9/720 -> 0.76666667 | J9: =I9 -> 0.76666667 | S9: =I9*T9 -> 191666.67 | T9: 250000 | V9: =(H9/10)*X9 -> 149040 | W9: =H9*X9 -> 1490400 | X9: 2700 | Y9: 120 | Z9: =F9-Y9 -> -9.6
A10: ООД 07 | B10: Информатика | D10: 5 | F10: 72 | H10: =F10*D10 -> 360 | I10: =H10/720 -> 0.5 | J10: =I10 -> 0.5 | S10: =I10*T10 -> 125000 | T10: 250000 | V10: =(H10/10)*X10 -> 97200 | W10: =H10*X10 -> 972000 | X10: 2700 | Y10: 48 | Z10: =F10-Y10 -> 24
A11: ООД 08 | B11: Начальная военная и технологическая подготовка (+полевые сборы -30 ч) | D11: 2.5 | F11: 96 | H11: =F11*D11 -> 240 | I11: =H11/720 -> 0.33333333 | J11: =I11 -> 0.33333333 | S11: =I11*T11 -> 83333.333 | T11: 250000 | V11: =(H11/10)*X11 -> 96000 | W11: =H11*X11 -> 960000 | X11: 4000 | Y11: 96 | Z11: =F11-Y11 -> 0
A12: ООД 09 | B12: Физическая культура | D12: 2 | F12: 120 | H12: =F12*D12 -> 240 | I12: =H12/720 -> 0.33333333 | J12: =I12 -> 0.33333333 | S12: =I12*T12 -> 83333.333 | T12: 250000 | V12: =(H12/10)*X12 -> 96000 | W12: =H12*X12 -> 960000 | X12: 4000 | Y12: 120 | Z12: =F12-Y12 -> 0
A13: ООД 10 | B13: Физика | D13: 5 | F13: 110.4 | H13: =F13*D13 -> 552 | I13: =H13/720 -> 0.76666667 | J13: =I13 -> 0.76666667 | S13: =I13*T13 -> 191666.67 | T13: 250000 | V13: =(H13/10)*X13 -> 149040 | W13: =H13*X13 -> 1490400 | X13: 2700 | Y13: 96 | Z13: =F13-Y13 -> 14.4
A14: ООД 11 | B14: Химия | D14: 5 | F14: 96 | H14: =F14*D14 -> 480 | I14: =H14/720 -> 0.66666667 | J14: =I14 -> 0.66666667 | S14: =I14*T14 -> 166666.67 | T14: 250000 | V14: =(H14/10)*X14 -> 129600 | W14: =H14*X14 -> 1296000 | X14: 2700 | Y14: 96 | Z14: =F14-Y14 -> 0
A15: ООД 12 | B15: География | D15: 5 | F15: 110.4 | H15: =F15*D15 -> 552 | I15: =H15/720 -> 0.76666667 | J15: =I15 -> 0.76666667 | S15: =I15*T15 -> 191666.67 | T15: 250000 | V15: =(H15/10)*X15 -> 149040 | W15: =H15*X15 -> 1490400 | X15: 2700 | Y15: 96 | Z15: =F15-Y15 -> 14.4
A16: ООД 13 | B16: Биология | D16: 2.5 | F16: 72 | H16: =F16*D16 -> 180 | I16: =H16/720 -> 0.25 | J16: =I16 -> 0.25 | S16: =I16*T16 -> 62500 | T16: 250000 | V16: =(H16/10)*X16 -> 72000 | W16: =H16*X16 -> 720000 | X16: 4000 | Y16: 72 | Z16: =F16-Y16 -> 0
A17: ООД 14 | B17: Всемирная история | D17: 5 | F17: 72 | H17: =F17*D17 -> 360 | I17: =H17/720 -> 0.5 | J17: =I17 -> 0.5 | S17: =I17*T17 -> 125000 | T17: 250000 | V17: =(H17/10)*X17 -> 97200 | W17: =H17*X17 -> 972000 | X17: 2700 | Y17: 96 | Z17: =F17-Y17 -> -24
A18: ООД 15 | B18: Курс "Глобальные компетенции" | D18: 2.5 | F18: 24 | H18: =F18*D18 -> 60 | I18: =H18/720 -> 0.083333333 | J18: =I18 -> 0.083333333 | S18: =I18*T18 -> 20833.333 | T18: 250000 | V18: =(H18/10)*X18 -> 24000 | W18: =H18*X18 -> 240000 | X18: 4000 | Y18: 24 | Z18: =F18-Y18 -> 0
A19: ООД 16 | B19: Графика и проектирование \ Индивидуальный проект | D19: 5 | F19: 72 | H19: =F19*D19 -> 360 | I19: =H19/720 -> 0.5 | J19: =I19 -> 0.5 | S19: =I19*T19 -> 125000 | T19: 250000 | V19: =(H19/10)*X19 -> 144000 | W19: =H19*X19 -> 1440000 | X19: 4000 | Y19: 48 | Z19: =F19-Y19 -> 24
A20: ПА 01 | B20: Промежуточная аттестация | D20: 10 | H20: =F20*D20 -> 0 | I20: =H20/720 -> 0 | J20: =I20 -> 0 | S20: =I20*T20 -> 0 | T20: 250000 | V20: =(H20/10)*2700 -> 0 | W20: =H20*X20 -> 0 | X20: 2700 | Y20: 72
B21: Итого ООД | H21: =F21*D21 -> 0 | I21: =H21/720 -> 0 | J21: =SUM(J4:J20) -> 9.1 | K21: =SUM(K4:K20) -> 0 | S21: =SUM(S4:S20) -> 2275000 | V21: =SUM(V4:V20) -> 1909440 | W21: =SUM(W4:W20) -> 19094400
A22: ООМ 1 | B22: Развитие и совершенствование физических качеств/ | D22: 2 | F22: 96 | G22: 29 | H22: =(F22*D22)+(G22*E22) -> 192 | I22: =H22/720 -> 0.26666667 | J22: =I22 -> 0.26666667 | S22: =I22*T22 -> 66666.667 | T22: 250000 | V22: =(H22/10)*X22 -> 76800 | W22: =H22*X22 -> 768000 | X22: 4000
A23: ООМ 2 | B23: Применение информационно-коммуникационных и цифровых технологий (ИКТ) / | D23: 3 | E23: 1 | F23: 96 | G23: 29 | H23: =(F23*D23)+(G23*E23) -> 317 | I23: =H23/720 -> 0.44027778 | J23: =I23 -> 0.44027778 | S23: =I23*T23 -> 110069.44 | T23: 250000 | V23: =(H23/10)*2700 -> 85590 | W23: =H23*X23 -> 1268000 | X23: 4000
A24: ООМ 3 | B24: Применение базовых знаний экономики и основ предпринимательства / Структура отрасли/ Менеджмент в профессиональной деятельности | D24: 3 | E24: 1 | F24: 48 | G24: 15 | H24: =(F24*D24)+(G24*E24) -> 159 | I24: =H24/720 -> 0.22083333 | J24: =I24 -> 0.22083333 | S24: =I24*T24 -> 55208.333 | T24: 250000 | V24: =(H24/10)*2700 -> 42930 | W24: =H24*X24 -> 636000 | X24: 4000
A25: ООМ 4 | B25: Применение основ социальных наук для социализации и адаптации в обществе и трудовом коллективе | D25: 3 | E25: 1 | F25: 120 | G25: 51 | H25: =(F25*D25)+(G25*E25) -> 411 | I25: =H25/720 -> 0.57083333 | J25: =I25 -> 0.57083333 | S25: =I25*T25 -> 142708.33 | T25: 250000 | V25: =(H25/10)*2700 -> 110970 | W25: =H25*X25 -> 1644000 | X25: 4000
B26: Промежуточная аттестация | H26: =F26*D26 -> 0 | I26: =H26/720 -> 0 | S26: =I26*T26 -> 0
B27: Итого ООМ | H27: =F27*D27 -> 0 | I27: =H27/720 -> 0 | J27: =SUM(J22:J26) -> 1.4986111 | K27: =SUM(K22:K26) -> 0 | S27: =SUM(S22:S26) -> 374652.78 | V27: =SUM(V22:V26) -> 316290 | W27: =SUM(W22:W26) -> 4316000
A29: ПМ 1 | B29: Создание web-страниц, сайтов с применением web-технологий | D29: 6 | E29: 1 | F29: 168 | G29: 84 | H29: =(F29*D29)+(G29*E29) -> 1092 | I29: =H29/720 -> 1.5166667 | J29: =I29 -> 1.5166667 | L29: =I29*T29 -> 530833.33 | M29: 72 | N29: =M29*2700 -> 194400 | R29: =S29/J29 -> 350000 | S29: =I29*T29 -> 530833.33 | T29: 350000 | U29: =V29/J29 -> 194400 | V29: =(H29/10)*2700 -> 294840 | W29: =H29*X29 -> 2948400 | X29: 2700
A30: ПМ 2 | B30: Прикладное программирование | D30: 6 | E30: 1 | F30: 264 | G30: 216 | H30: =(F30*D30)+(G30*E30) -> 1800 | I30: =H30/720 -> 2.5 | J30: =I30 -> 2.5 | L30: =I30*T30 -> 875000 | M30: 96 | N30: =M30*2700 -> 259200 | R30: =S30/J30 -> 350000 | S30: =I30*T30 -> 875000 | T30: 350000 | U30: =V30/J30 -> 194400 | V30: =(H30/10)*2700 -> 486000 | W30: =H30*X30 -> 4860000 | X30: 2700
A31: ПМ 3 | B31: Разработка модулей программного обеспечения для компьютерных систем | D31: 3 | E31: 2 | F31: 336 | G31: 156 | H31: =(F31*D31)+(G31*E31) -> 1320 | I31: =H31/720 -> 1.8333333 | J31: =I31 -> 1.8333333 | L31: =I31*T31 -> 641666.67 | M31: 96 | N31: =M31*2700 -> 259200 | R31: =S31/J31 -> 350000 | S31: =I31*T31 -> 641666.67 | T31: 350000 | U31: =V31/J31 -> 194400 | V31: =(H31/10)*2700 -> 356400 | W31: =H31*X31 -> 3564000 | X31: 2700
A32: ПМ 4 | B32: Разработка браузерных приложений | D32: 3 | E32: 2 | F32: 360 | G32: 130 | H32: =(F32*D32)+(G32*E32) -> 1340 | I32: =H32/720 -> 1.8611111 | J32: =I32 -> 1.8611111 | L32: =I32*T32 -> 651388.89 | M32: 96 | N32: =M32*2700 -> 259200 | R32: =S32/J32 -> 350000 | S32: =I32*T32 -> 651388.89 | T32: 350000 | U32: =V32/J32 -> 194400 | V32: =(H32/10)*2700 -> 361800 | W32: =H32*X32 -> 3618000 | X32: 2700
A33: ПМ 5 | B33: Разработка веб приложений на React | D33: 3 | E33: 2 | F33: 264 | G33: 108 | H33: =(F33*D33)+(G33*E33) -> 1008 | I33: =H33/720 -> 1.4 | J33: =I33 -> 1.4 | L33: =I33*T33 -> 490000 | M33: 96 | N33: =M33*2700 -> 259200 | R33: =S33/J33 -> 350000 | S33: =I33*T33 -> 490000 | T33: 350000 | U33: =V33/J33 -> 194400 | V33: =(H33/10)*2700 -> 272160 | W33: =H33*X33 -> 2721600 | X33: 2700
A34: ПМ 6 | B34: Поддержка и тестирование программных модулей | D34: 3 | E34: 2 | F34: 144 | G34: 65 | H34: =(F34*D34)+(G34*E34) -> 562 | I34: =H34/720 -> 0.78055556 | J34: =I34 -> 0.78055556 | L34: =I34*T34 -> 273194.44 | M34: 96 | N34: =M34*2700 -> 259200 | R34: =S34/J34 -> 350000 | S34: =I34*T34 -> 273194.44 | T34: 350000 | U34: =V34/J34 -> 194400 | V34: =(H34/10)*2700 -> 151740 | W34: =H34*X34 -> 1517400 | X34: 2700
A35: ПМ 7 | B35: Сопровождение и обслуживание программного обеспечения компьютерных систем | D35: 1 | E35: 1 | F35: 144 | G35: 84 | H35: =(F35*D35)+(G35*E35) -> 228 | I35: =H35/720 -> 0.31666667 | J35: =I35 -> 0.31666667 | M35: 96 | N35: =M35*2700 -> 259200 | R35: =S35/J35 -> 350000 | S35: =I35*T35 -> 110833.33 | T35: 350000 | U35: =V35/J35 -> 194400 | V35: =(H35/10)*2700 -> 61560 | W35: =H35*X35 -> 615600 | X35: 2700
A36: ПМ 8 | B36: Разработка, администрирование и защита баз данных | D36: 1 | E36: 1 | F36: 144 | G36: 84 | H36: =(F36*D36)+(G36*E36) -> 228 | I36: =H36/720 -> 0.31666667 | J36: =I36 -> 0.31666667 | M36: 96 | N36: =M36*2700 -> 259200 | R36: =S36/J36 -> 350000 | S36: =I36*T36 -> 110833.33 | T36: 350000 | U36: =V36/J36 -> 194400 | V36: =(H36/10)*2700 -> 61560 | W36: =H36*X36 -> 615600 | X36: 2700
B37: Промежуточной аттестации (нед) | D37: 1 | E37: 1 | F37: 96 | G37: 44 | H37: =(F37*D37)+(G37*E37) -> 140 | I37: =H37/720 -> 0.19444444 | J37: =I37 -> 0.19444444 | R37: =S37/J37 -> 350000 | S37: =I37*T37 -> 68055.556 | T37: 350000 | U37: =V37/J37 -> 194400 | V37: =(H37/10)*2700 -> 37800 | W37: =H37*X37 -> 378000 | X37: 2700
B38: Итоговая аттестация | D38: 1 | E38: 1 | F38: 72 | G38: 22 | H38: =(F38*D38)+(G38*E38) -> 94 | I38: =H38/720 -> 0.13055556 | J38: =I38 -> 0.13055556 | R38: =S38/J38 -> 350000 | S38: =I38*T38 -> 45694.444 | T38: 350000 | U38: =V38/J38 -> 194400 | V38: =(H38/10)*2700 -> 25380 | W38: =H38*X38 -> 253800 | X38: 2700
B39: Итого ПМ | J39: =SUM(J29:J38) -> 10.85 | K39: =SUM(K29:K38) -> 0 | L39: =SUM(L29:L38) -> 3462083.3 | M39: =SUM(M29:M38) -> 744 | N39: =SUM(N29:N38) -> 2008800 | O39: =SUM(O29:O38) -> 0 | P39: =SUM(P29:P38) -> 0 | Q39: =SUM(Q29:Q38) -> 0 | ... S39: =SUM(S29:S38) -> 3797500 | U39: =SUM(U29:U38) -> 1944000 | V39: =SUM(V29:V38) -> 2109240 | W39: =SUM(W29:W38) -> 21092400
B40: Итого | J40: =J21+J27+J39 -> 21.448611 | S40: =S21+S27+S39 -> 6447152.8 | U40: =U21+U27+U39 -> 1944000 | V40: =V21+V27+V39 -> 4334970 | W40: =W21+W27+W39 -> 44502800
L42: =L39+Q39+V27+V21 -> 5687813.3 | S42: 76924212 | V42: 76924212
...

Sheet Расчет часов, ставок на препод 
L1: В штате
A2: Индекс | B2: Предмет | C2: Квалифика | D2: Количество очных групп | E2: Кол-во очных групп новый набор | F2: Количество заочных групп | G2: Всего часов на предмет очно | H2: Всего часов на предмет заочно | I2: Всего часов | J2: Ставка | K2: Количество преподавателей | L2: В месяц | M2: Оклад за полную ставку
A4: ООД 01 | B4: Казахский язык и литература | C4: Все на базе 9 кл | D4: 6 | G4: 96 | I4: =G4*D4 -> 576 | J4: =I4/720 -> 0.8 | K4: =J4 -> 0.8 | L4: =J4*M4 -> 155520 | M4: 194400
A5: ООД 02 | B5: Русский язык | C5: Все на базе 9 кл | D5: 6 | G5: 96 | I5: =G5*D5 -> 576 | J5: =I5/720 -> 0.8 | K5: =J5 -> 0.8 | L5: =J5*M5 -> 155520 | M5: 194400
A6: ООД 03 | B6: Русская литература | C6: Все на базе 9 кл | D6: 6 | G6: 96 | I6: =G6*D6 -> 576 | J6: =I6/720 -> 0.8 | K6: =J6 -> 0.8 | L6: =J6*M6 -> 155520 | M6: 194400
A7: ООД 04 | B7: Иностранный язык | C7: Все на базе 9 кл | D7: 6 | G7: 96 | I7: =G7*D7 -> 576 | J7: =I7/720 -> 0.8 | K7: =J7 -> 0.8 | L7: =J7*M7 -> 155520 | M7: 194400
A8: ООД 05 | B8: История Казахстана | C8: Все на базе 9 кл | D8: 6 | G8: 72 | I8: =G8*D8 -> 432 | J8: =I8/720 -> 0.6 | K8: =J8 -> 0.6 | L8: =J8*M8 -> 116640 | M8: 194400
A9: ООД 06 | B9: Математика | C9: Все на базе 9 кл | D9: 6 | G9: 120 | I9: =G9*D9 -> 720 | J9: =I9/720 -> 1 | K9: =J9 -> 1 | L9: =J9*M9 -> 194400 | M9: 194400
A10: ООД 07 | B10: Информатика | C10: Все на базе 9 кл | D10: 6 | G10: 72 | I10: =G10*D10 -> 432 | J10: =I10/720 -> 0.6 | K10: =J10 -> 0.6 | L10: =J10*M10 -> 116640 | M10: 194400
A11: ООД 08 | B11: Начальная военная и технологическая подготовка | C11: Все на базе 9 кл | D11: 3 | G11: 96 | I11: =G11*D11 -> 288 | J11: =I11/720 -> 0.4 | K11: =J11 -> 0.4 | L11: =J11*M11 -> 115200 | M11: 288000
A12: ООД 09 | B12: Физическая культура | C12: Все на базе 9 кл | D12: 3 | G12: 120 | I12: =G12*D12 -> 360 | J12: =I12/720 -> 0.5 | K12: =J12 -> 0.5 | L12: =J12*M12 -> 144000 | M12: 288000
A13: ООД 10 | B13: Физика | C13: Все на базе 9 кл | D13: 6 | G13: 96 | I13: =G13*D13 -> 576 | J13: =I13/720 -> 0.8 | K13: =J13 -> 0.8 | L13: =J13*M13 -> 155520 | M13: 194400
A14: ООД 11 | B14: Химия | C14: Все на базе 9 кл | D14: 3 | G14: 96 | I14: =G14*D14 -> 288 | J14: =I14/720 -> 0.4 | K14: =J14 -> 0.4 | L14: =J14*M14 -> 115200 | M14: 288000
A15: ООД 12 | B15: География | C15: РПО, ТИС, ВД, ТИБ | D15: 2 | G15: 72 | I15: =G15*D15 -> 144 | J15: =I15/720 -> 0.2 | K15: =J15 -> 0.2 | L15: =J15*M15 -> 57600 | M15: 288000
... A20: ООД 12 | B20: География | C20: Маркетинг, Менеджмент | D20: 1 | G20: 96 | I20: =G20*D20 -> 96 | J20: =I20/720 -> 0.13333333 | K20: =J20 -> 0.13333333 | L20: =J20*M20 -> 38400 | M20: 288000
B21: Промежуточной аттестации (нед) | D21: 6 | G21: 48 | I21: =G21*D21 -> 288 | J21: =I21/720 -> 0.4 | K21: =J21 -> 0.4 | L21: =J21*M21 -> 77760 | M21: 194400
A22: ООД 01 | B22: Казахский язык | D22: 2 | G22: 96 | I22: =G22*D22 -> 192 | J22: =I22/720 -> 0.26666667 | K22: =J22 -> 0.26666667 | L22: =J22*M22 -> 51840 | M22: 194400
A23: ООД 02 | B23: Казахская литература | D23: 2 | G23: 96 | I23: =G23*D23 -> 192 | J23: =I23/720 -> 0.26666667 | K23: =J23 -> 0.26666667 | L23: =J23*M23 -> 51840 | M23: 194400
A24: ООД 03 | B24: Русский язык и литература | D24: 2 | G24: 96 | I24: =G24*D24 -> 192 | J24: =I24/720 -> 0.26666667 | K24: =J24 -> 0.26666667 | L24: =J24*M24 -> 51840 | M24: 194400
A25: ООД 04 | B25: Иностранный язык | D25: 2 | G25: 96 | I25: =G25*D25 -> 192 | J25: =I25/720 -> 0.26666667 | K25: =J25 -> 0.26666667 | L25: =J25*M25 -> 51840 | M25: 194400
A26: ООД 05 | B26: История Казахстана | D26: 2 | G26: 72 | I26: =G26*D26 -> 144 | J26: =I26/720 -> 0.2 | K26: =J26 -> 0.2 | L26: =J26*M26 -> 38880 | M26: 194400
A27: ООД 06 | B27: Математика | D27: 2 | G27: 120 | I27: =G27*D27 -> 240 | J27: =I27/720 -> 0.33333333 | K27: =J27 -> 0.33333333 | L27: =J27*M27 -> 64800 | M27: 194400
A28: ООД 07 | B28: Информатика | D28: 2 | G28: 72 | I28: =G28*D28 -> 144 | J28: =I28/720 -> 0.2 | K28: =J28 -> 0.2 | L28: =J28*M28 -> 38880 | M28: 194400
A29: ООД 08 | B29: Начальная военная и технологическая подготовка | D29: 2 | G29: 96 | I29: =G29*D29 -> 192 | J29: =I29/720 -> 0.26666667 | K29: =J29 -> 0.26666667 | L29: =J29*M29 -> 76800 | M29: 288000
A30: ООД 09 | B30: Физическая культура | D30: 2 | G30: 120 | I30: =G30*D30 -> 240 | J30: =I30/720 -> 0.33333333 | K30: =J30 -> 0.33333333 | L30: =J30*M30 -> 96000 | M30: 288000
A31: ООД 10 | B31: Физика | D31: 2 | G31: 96 | I31: =G31*D31 -> 192 | J31: =I31/720 -> 0.26666667 | K31: =J31 -> 0.26666667 | L31: =J31*M31 -> 51840 | M31: 194400
A32: ООД 11 | B32: Химия | D32: 2 | G32: 96 | I32: =G32*D32 -> 192 | J32: =I32/720 -> 0.26666667 | K32: =J32 -> 0.26666667 | L32: =J32*M32 -> 76800 | M32: 288000
A33: ООД 12 | B33: География | D33: 2 | G33: 72 | I33: =G33*D33 -> 144 | J33: =I33/720 -> 0.2 | K33: =J33 -> 0.2 | L33: =J33*M33 -> 57600 | M33: 288000
... A37: ООД 16 | B37: Графика и проектирование \ Индивидуальный проект | D37: 2 | G37: 72 | I37: =G37*D37 -> 144 | J37: =I37/720 -> 0.2 | K37: =J37 -> 0.2 | L37: =J37*M37 -> 38880 | M37: 194400
B38: Промежуточной аттестации (нед) | D38: 2 | G38: 48 | I38: =G38*D38 -> 96 | J38: =I38/720 -> 0.13333333 | K38: =J38 -> 0.13333333 | L38: =J38*M38 -> 25920 | M38: 194400
B39: Итого ООД | D39: =SUM(D4:D38) -> 118 | E39: =SUM(E4:E38) -> 0 | F39: =SUM(F4:F38) -> 0 | G39: =SUM(G4:G38) -> 2928 | H39: =SUM(H4:H38) -> 0 | I39: =SUM(I4:I38) -> 9768 | J39: =SUM(J4:J38) -> 13.566667 | K39: =SUM(K4:K38) -> 13.566667 | ... M39: =SUM(M4:M38) -> 8020800
A40: ООМ 1 | B40: Развитие и совершенствование физических качеств/ | C40: 18, 19, 20 РПО/25, новый набор 2026 | D40: 3 | E40: 1 | G40: 96 | I40: =((G40*D40)+(G40*E40))/2 -> 192 | J40: =I40/720 -> 0.26666667 | K40: =J40 -> 0.26666667 | L40: =J40*M40 -> 76800 | M40: 288000
A41: ООМ 2 | B41: Применение информационно-коммуникационных и цифровых технологий (ИКТ) | C41: 18, 19, 20 РПО/25, новый набор 2026 | D41: 3 | E41: 1 | G41: 96 | I41: =((G41*D41)+(G41*E41))/2 -> 192 | J41: =I41/720 -> 0.26666667 | K41: =J41 -> 0.26666667 | L41: =J41*M41 -> 76800 | M41: 288000
A42: ООМ 3 | B42: Применение базовых знаний экономики и основ предпринимательства | C42: 18, 19, 20 РПО/25, новый набор 2026 | D42: 3 | E42: 1 | G42: 48 | I42: =((G42*D42)+(G42*E42))/2 -> 96 | J42: =I42/720 -> 0.13333333 | K42: =J42 -> 0.13333333 | L42: =J42*M42 -> 38400 | M42: 288000
A43: ООМ 4 | B43: Применение основ социальных наук для социализации и адаптации в обществе и трудовом коллективе | C43: 18, 19, 20 РПО/25, новый набор 2026 | D43: 3 | E43: 1 | G43: 96 | I43: =((G43*D43)+(G43*E43))/2 -> 192 | J43: =I43/720 -> 0.26666667 | K43: =J43 -> 0.26666667 | L43: =J43*M43 -> 76800 | M43: 288000
A44: ООМ 1 | B44: Развитие и совершенствование физических качеств/ | C44: ТИС | D44: 1 | G44: 96 | I44: =(G44*D44)+(G44*E44) -> 96 | J44: =I44/720 -> 0.13333333 | K44: =J44 -> 0.13333333 | L44: =J44*M44 -> 25920 | M44: 194400
A45: ООМ 2 | B45: Применение информационно-коммуникационных и цифровых технологий (ИКТ) | C45: ТИС | D45: 1 | G45: 96 | I45: =(G45*D45)+(G45*E45) -> 96 | J45: =I45/720 -> 0.13333333 | K45: =J45 -> 0.13333333 | L45: =J45*M45 -> 25920 | M45: 194400
A46: ООМ 3 | B46: Применение базовых знаний экономики и основ предпринимательства | C46: ТИС | D46: 1 | G46: 48 | I46: =(G46*D46)+(G46*E46) -> 48 | J46: =I46/720 -> 0.066666667 | K46: =J46 -> 0.066666667 | L46: =J46*M46 -> 12960 | M46: 194400
A47: ООМ 4 | B47: Применение основ социальных наук для социализации и адаптации в обществе и трудовом коллективе | C47: ТИС | D47: 1 | G47: 96 | I47: =(G47*D47)+(G47*E47) -> 96 | J47: =I47/720 -> 0.13333333 | K47: =J47 -> 0.13333333 | L47: =J47*M47 -> 25920 | M47: 194400
A48: ООМ 1 | B48: Развитие и совершенствование физических качеств/ | C48: ТИС | F48: 1 | G48: 30 | I48: =(G48*F48) -> 30 | J48: =I48/720 -> 0.041666667 | K48: =J48 -> 0.041666667 | L48: =J48*M48 -> 8100 | M48: 194400
...

Sheet Штатное расписание на 2026-2027
A1: ТОО Колледж Хекслет
A2: (официальное наименование организации)
A4: Утверждено
A5: Приказом от «___» ___________ 20__ года № ______
A6: штат в количестве _____________ единиц
A7: с месячным фондом заработной платы _______________ тенге
A9: Штатное расписание
A10: на 2026 - 2027 учебный год
A12: № п/п | B12: Должность (профессия) | C12: Количество штатных единиц | D12: тарифная ставка | E12: Оклад тенге | F12: По часовая оплата | H12: Месячный фонд заработной платы, тенге | I12: Годвой фонд заработной платы, тенге | J12: Примечание
F13: Количество часов | G13: Ставка
A14: =COUNTA($B$14:B14) -> 1 | B14: Директор | C14: 1 | D14: 1 | E14: 600000 | H14: =E14*D14*C14 -> 600000 | I14: =H14*12 -> 7200000 | J14: =I14*1.48 -> 10656000
A15: =COUNTA($B$14:B15) -> 2 | B15: Заместитель директора по воспитательной работе | C15: 1 | D15: 1 | E15: 625000 | H15: =E15*D15*C15 -> 625000 | I15: =H15*12 -> 7500000 | J15: =I15*1.17 -> 8775000
A16: =COUNTA($B$14:B16) -> 3 | B16: Заместитель директора по учебной работе | C16: 1 | D16: 1 | E16: 450000 | H16: =E16*D16*C16 -> 450000 | I16: =H16*12 -> 5400000 | J16: =I16*1.17 -> 6318000
A17: =COUNTA($B$14:B17) -> 4 | B17: Заведующий хозяйством | C17: 1 | D17: 0.5 | E17: 300000 | H17: =E17*D17*C17 -> 150000 | I17: =H17*12 -> 1800000 | J17: =I17*1.17 -> 2106000
A18: =COUNTA($B$14:B18) -> 5 | B18: Заведующий центром развития карьеры | C18: 1 | D18: 1 | E18: 350000 | H18: =E18*D18*C18 -> 350000 | I18: =H18*12 -> 4200000 | J18: =I18*1.17 -> 4914000
A19: =COUNTA($B$14:B19) -> 6 | B19: Секретарь учебно-методической части | C19: 1 | D19: 1 | E19: 250000 | H19: =E19*D19*C19 -> 250000 | I19: =H19*12 -> 3000000 | J19: =I19*1.17 -> 3510000
A20: =COUNTA($B$14:B20) -> 7 | B20: Методист (специалист по учебно-методической работе) | C20: 1 | D20: 1 | E20: 300000 | H20: =E20*D20*C20 -> 300000 | I20: =H20*12 -> 3600000 | J20: =I20*1.17 -> 4212000
A21: =COUNTA($B$14:B21) -> 8 | B21: Заведующий отделом кадров (секретарь) | C21: 1 | D21: 1 | E21: 250000 | H21: =E21*D21*C21 -> 250000 | I21: =H21*12 -> 3000000 | J21: =I21*1.17 -> 3510000
A22: =COUNTA($B$14:B22) -> 9 | B22: Системный администратор, администратор сайта | C22: 1 | D22: 0.5 | E22: 250000 | H22: =E22*D22*C22 -> 125000 | I22: =H22*12 -> 1500000 | J22: =I22*1.17 -> 1755000
A23: =COUNTA($B$14:B23) -> 10 | B23: Менеджер приемной комиссии | C23: 1 | D23: 1 | E23: 250000 | H23: =E23*D23*C23 -> 250000 | I23: =H23*12 -> 3000000 | J23: =I23*1.17 -> 3510000
A24: =COUNTA($B$14:B24) -> 11 | B24: Бухгалтер | C24: 1 | D24: 1 | E24: 520000 | H24: =E24*D24*C24 -> 520000 | I24: =H24*12 -> 6240000 | J24: =I24*1.17 -> 7300800
A25: =COUNTA($B$14:B25) -> 12 | B25: Медицинская сестра | C25: 1 | D25: 0.25 | E25: 150000 | H25: =E25*D25*C25 -> 37500 | I25: =H25*12 -> 450000 | J25: =I25*1.17 -> 526500
A26: =COUNTA($B$14:B26) -> 13 | B26: Педагог- психолог | C26: 1 | D26: 0.5 | E26: 200000 | H26: =E26*D26*C26 -> 100000 | I26: =H26*12 -> 1200000 | J26: =I26*1.17 -> 1404000
A27: =COUNTA($B$14:B27) -> 14 | B27: Педагог-Организатор | C27: 1 | D27: 0.5 | E27: 200000 | H27: =E27*D27*C27 -> 100000 | I27: =H27*12 -> 1200000 | J27: =I27*1.17 -> 1404000 | K27: ?
A28: =COUNTA($B$14:B28) -> 15 | B28: Технически персанал | C28: 1 | D28: 1 | E28: 250000 | H28: =E28*D28*C28 -> 250000 | I28: =H28*12 -> 3000000 | J28: =I28*1.17 -> 3510000 | K28: =SUM(H14:H28) -> 4357500 | L28: =SUM(I14:I28) -> 52290000 | M28: =SUM(J14:J28) -> 63411300
A30: =COUNTA($B$14:B31) -> 17 | B30: Куратор | C30: 5 | D30: 1 | E30: 250000 | H30: =E30*D30*C30 -> 1250000 | I30: =H30*12 -> 15000000 | J30: =I30*1.17 -> 17550000
A31: =COUNTA($B$14:B31) -> 17 | B31: Преподаватель по Казахскому языку и литературе | C31: 1 | D31: =F31/720 -> 0.8 | E31: ='Расчет часов, ставок на препод '!M4 -> 194400 | F31: ='Расчет часов, ставок на препод '!I4 -> 576 | H31: ='Расчет часов, ставок на препод '!L4 -> 155520 | I31: =H31*12 -> 1866240
A32: =COUNTA($B$14:B32) -> 18 | B32: Преподаватель по Русскому языку | C32: 1 | D32: =F32/720 -> 0.8 | E32: ='Расчет часов, ставок на препод '!M5 -> 194400 | F32: ='Расчет часов, ставок на препод '!I5 -> 576 | H32: ='Расчет часов, ставок на препод '!L5 -> 155520 | I32: =H32*12 -> 1866240
A33: =COUNTA($B$14:B33) -> 19 | B33: Преподаватель по Русской литературе | C33: 1 | D33: =F33/720 -> 0.8 | E33: ='Расчет часов, ставок на препод '!M6 -> 194400 | F33: ='Расчет часов, ставок на препод '!I6 -> 576 | H33: ='Расчет часов, ставок на препод '!L6 -> 155520 | I33: =H33*12 -> 1866240
A34: =COUNTA($B$14:B34) -> 20 | B34: Преподаватель по Иностранному языку | C34: 1 | D34: =F34/720 -> 0.8 | E34: ='Расчет часов, ставок на препод '!M7 -> 194400 | F34: ='Расчет часов, ставок на препод '!I7 -> 576 | H34: ='Расчет часов, ставок на препод '!L7 -> 155520 | I34: =H34*12 -> 1866240
A35: =COUNTA($B$14:B35) -> 21 | B35: Преподаватель по Истории Казахстана | C35: 1 | D35: =F35/720 -> 0.6 | E35: ='Расчет часов, ставок на препод '!M8 -> 194400 | F35: ='Расчет часов, ставок на препод '!I8 -> 432 | H35: ='Расчет часов, ставок на препод '!L8 -> 116640 | I35: =H35*12 -> 1399680
A36: =COUNTA($B$14:B36) -> 22 | B36: Преподаватель по Математике | C36: 1 | D36: =F36/720 -> 1 | E36: ='Расчет часов, ставок на препод '!M9 -> 194400 | F36: ='Расчет часов, ставок на препод '!I9 -> 720 | H36: ='Расчет часов, ставок на препод '!L9 -> 194400 | I36: =H36*12 -> 2332800
A37: =COUNTA($B$14:B37) -> 23 | B37: Преподаватель по Информатике | C37: 1 | D37: =F37/720 -> 0.6 | E37: ='Расчет часов, ставок на препод '!M10 -> 194400 | F37: ='Расчет часов, ставок на препод '!I10 -> 432 | H37: ='Расчет часов, ставок на препод '!L10 -> 116640 | I37: =H37*12 -> 1399680
A38: =COUNTA($B$14:B38) -> 24 | B38: Преподаватель по Начальной военной и технологической подготовке | C38: 1 | D38: =F38/720 -> 0.4 | E38: ='Расчет часов, ставок на препод '!M11 -> 288000 | F38: ='Расчет часов, ставок на препод '!I11 -> 288 | H38: ='Расчет часов, ставок на препод '!L11 -> 115200 | I38: =H38*12 -> 1382400
A39: =COUNTA($B$14:B39) -> 25 | B39: Преподаватель по Физической культуре | C39: 1 | D39: =F39/720 -> 0.5 | E39: ='Расчет часов, ставок на препод '!M12 -> 288000 | F39: ='Расчет часов, ставок на препод '!I12 -> 360 | H39: ='Расчет часов, ставок на препод '!L12 -> 144000 | I39: =H39*12 -> 1728000
A40: =COUNTA($B$14:B40) -> 26 | B40: Преподаватель по Физике | C40: 1 | D40: =F40/720 -> 0.8 | E40: ='Расчет часов, ставок на препод '!M13 -> 194400 | F40: ='Расчет часов, ставок на препод '!I13 -> 576 | H40: ='Расчет часов, ставок на препод '!L13 -> 155520 | I40: =H40*12 -> 1866240
A41: =COUNTA($B$14:B41) -> 27 | B41: Преподаватель по Химии | C41: 1 | D41: =F41/720 -> 0.4 | E41: ='Расчет часов, ставок на препод '!M14 -> 288000 | F41: ='Расчет часов, ставок на препод '!I14 -> 288 | H41: ='Расчет часов, ставок на препод '!L14 -> 115200 | I41: =H41*12 -> 1382400
