Workbook

Sheet график уч проц
B1: ТОО "КОЛЛЕДЖ ХЕКСЛЕТ"
A30: курсы | B30: сентябрь | G30: октябрь | K30: ноябрь | O30: декабрь | T30: январь | X30: февраль | AB30: март | AG30: апрель | AK30: май | AO30: июнь | AT30: июль | AX30: август
A31: недели | B31: 2 | C31: 9 | D31: 16 | E31: 23 | F31: 30 IX | G31: 7 | H31: 14 | I31: 21 | J31: 28 X | K31: 4 | L31: 11 | M31: 18 | N31: 25 | O31: 2 | P31: 9 | Q31: 16 | R31: 23 | S31: 30 XII | T31: 6 | U31: 13 | V31: 20 | W31: 27 | X31: 3 | Y31: 10 | Z31: 17 | AA31: 24 | AB31: 3 | AC31: 10 | AD31: 17 | AE31: 24 | AF31: 31 III | AG31: 7 | AH31: 14 | AI31: 21 | AJ31: 28 IV | AK31: 5 | AL31: 12 | AM31: 19 | AN31: 26 | AO31: 2 | AP31: 9 | AQ31: 16 | AR31: 23 | AS31: 30 VI | AT31: 7 | AU31: 14 | AV31: 21 | AW31: 28 VII | AX31: 4 | AY31: 11 | AZ31: 18 | BA31: 25
B32: 6 | C32: 13 | D32: 20 | E32: 27 | F32: 4 X | G32: 11 | H32: 18 | I32: 25 | J32: 1 XI | K32: 8 | L32: 15 | M32: 22 | N32: 29 | O32: 6 | P32: 13 | Q32: 20 | R32: 27 | S32: 3 I | T32: 10 | U32: 17 | V32: 24 | W32: 31 | X32: 7 | Y32: 14 | Z32: 21 | AA32: 28 | AB32: 7 | AC32: 14 | AD32: 21 | AE32: 28 | AF32: 4 IV | AG32: 12 | AH32: 19 | AI32: 26 | AJ32: 2 V | AK32: 9 | AL32: 16 | AM32: 23 | AN32: 30 | AO32: 6 | AP32: 13 | AQ32: 20 | AR32: 27 | AS32: 4 VII | AT32: 11 | AU32: 18 | AV32: 25 | AW32: 1 VIII | AX32: 8 | AY32: 15 | AZ32: 22 | BA32: 29
A33: №нед | B33: 1 | C33: 2 | D33: 3 | E33: 4 | F33: 5 | G33: 6 | H33: 7 | I33: 8 | J33: 9 | K33: 10 | L33: 11 | M33: 12 | N33: 13 | O33: 14 | P33: 15 | Q33: 16 | R33: 17 | S33: 18 | T33: 19 | U33: 20 | V33: 21 | W33: 22 | X33: 23 | Y33: 24 | Z33: 25 | AA33: 26 | AB33: 27 | AC33: 28 | AD33: 29 | AE33: 30 | AF33: 31 | AG33: 32 | AH33: 33 | AI33: 34 | AJ33: 35 | AK33: 36 | AL33: 37 | AM33: 38 | AN33: 39 | AO33: 40 | AP33: 41 | AQ33: 42 | AR33: 43 | AS33: 44 | AT33: 45 | AU33: 46 | AV33: 47 | AW33: 48 | AX33: 49 | AY33: 50 | AZ33: 51 | BA33: 52
A34: I | B34: ТО | C34: ТО | D34: ТО | E34: ТО | F34: ТО | G34: ТО | H34: ТО | I34: ТО | J34: ТО | K34: ТО | L34: ТО | M34: ТО | N34: ТО | O34: ТО | P34: ТО | Q34: ТО | R34: ТО | S34: К | T34: К | U34: ТО | V34: ТО | W34: ТО | X34: ТО | Y34: ТО | Z34: ТО | AA34: ТО | AB34: ТО | AC34: ТО | AD34: ТО | AE34: ТО | AF34: ТО | AG34: ТО | AH34: ТО | AI34: ТО | AJ34: ТО | AK34: ТО | AL34: ТО | AM34: ТО | AN34: ТО | AO34: ПС | AP34: ПС | AQ34: ПА | AR34: ПА | AS34: Пдн | AT34: К | AU34: К | AV34: К | AW34: К | AX34: К | AY34: К | AZ34: К | BA34: К
A35: II | B35: ТО | C35: ТО | D35: ТО | E35: ТО | F35: ТО | G35: ТО | H35: ТО | I35: ТО | J35: ТО | K35: ТО | L35: ТО | M35: ТО | N35: ПП | O35: ПП | P35: ПП | Q35: ПП | R35: ПП | S35: К | T35: К | U35: ТО | V35: ТО | W35: ТО | X35: ТО | Y35: ТО | Z35: ТО | AA35: ТО | AB35: ТО | AC35: ТО | AD35: ТО | AE35: ТО | AF35: ПП | AG35: ПП | AH35: ПП | AI35: ПП | AJ35: ПП | AK35: ПП | AL35: ПП | AM35: ПП | AN35: ПП | AO35: ПП | AP35: ПП | AQ35: ПА | AR35: ПА | AS35: Пдн | AT35: К | AU35: К | AV35: К | AW35: К | AX35: К | AY35: К | AZ35: К | BA35: К
A36: III | B36: ТО | C36: ТО | D36: ТО | E36: ТО | F36: ТО | G36: ТО | H36: ТО | I36: ТО | J36: ТО | K36: ТО | L36: ПП | M36: ПП | N36: ПП | O36: ПП | P36: ПП | Q36: ПП | R36: ПП | S36: К | T36: К | U36: ТО | V36: ТО | W36: ТО | X36: ТО | Y36: ТО | Z36: ТО | AA36: ТО | AB36: ТО | AC36: ТО | AD36: ПП | AE36: ПП | AF36: ПП | AG36: ПП | AH36: ПП | AI36: ПП | AJ36: ПП | AK36: ПП | AL36: ПП | AM36: ПП | AN36: ПП | AO36: ПП | AP36: ПП | AQ36: ПА | AR36: ПА | AS36: Пдн | AT36: К | AU36: К | AV36: К | AW36: К | AX36: К | AY36: К | AZ36: К | BA36: К
A37: IV | B37: ТО | C37: ТО | D37: ТО | E37: ТО | F37: ТО | G37: ТО | H37: ТО | I37: ТО | J37: ПО | K37: ПО | L37: ПО | M37: ПО | N37: ПО | O37: ПО | P37: ПО | Q37: ПО | R37: ПО | S37: К | T37: К | U37: ПО | V37: ПО | W37: ПО | X37: ПО | Y37: ПО | Z37: ПО | AA37: ПО | AB37: ПО | AC37: ПО | AD37: ПО | AE37: ПО | AF37: ПО | AG37: ПО | AH37: ПО | AI37: ПО | AJ37: ПО | AK37: ДП | AL37: ДП | AM37: ДП | AN37: ДП | AO37: ДП | AP37: ДП | AQ37: ИА | AR37: ИА | AS37: Пдн
A39: Обозначения:
A40: ТО | B40: - теоретическое обучение
A41: ПО | B41: - производственное обучение
A42: ПП | B42: - профессиональная практика
A43: ПА | B43: - промежуточная аттестация
A44: К | B44: - каникулы
A45: Пдн | B45: - праздничные дни
A46: ИА | B46: - итоговая аттестация
A47: ПС | B47: - полевые сборы
A48: ДП | B48: - Дипломное проектирование
A52: курсы | D52: Теоретическое обучение | O52: Промежуточная аттестация | U52: Производственное обучение и профессиональная практика | AA52: Дипломное проектирование | AG52: Итоговая аттестация | AM52: Праздничные дни | AP52: Каникулы | AS52: Всего недель в учебном году
D53: недель | H53: кредиты | L53: часов
A55: I | D55: 39 | H55: =L55/24 -> 57 | L55: 1368 | O55: 72 | AM55: 1 | AP55: 10 | AS55: 52
A56: II | D56: 23 | H56: =L56/24 -> 43 | L56: ='Структура рабочего учебного пла'!Q57+'Структура рабочего учебного пла'!R57+'Структура рабочего учебного пла'!G66+'Структура рабочего учебного пла'!G77+'Структура рабочего учебного пла'!R90 -> 1032 | O56: ='Структура рабочего учебного пла'!Q131+'Структура рабочего учебного пла'!R131 -> 24 | U56: ='Структура рабочего учебного пла'!G67+'Структура рабочего учебного пла'!G78 -> 384 | AM56: 1 | AP56: 10 | AS56: 52
A57: III | D57: 19 | H57: =L57/24 -> 34.5 | L57: ='Структура рабочего учебного пла'!S84+'Структура рабочего учебного пла'!S85+'Структура рабочего учебного пла'!S86+'Структура рабочего учебного пла'!S87+'Структура рабочего учебного пла'!G97+'Структура рабочего учебного пла'!G107+'Структура рабочего учебного пла'!T118 -> 828 | O57: ='Структура рабочего учебного пла'!S131+'Структура рабочего учебного пла'!T131 -> 36 | U57: ='Структура рабочего учебного пла'!S89+'Структура рабочего учебного пла'!T98+'Структура рабочего учебного пла'!T108 -> 576 | AM57: 1 | AP57: 10 | AS57: 52
A58: IV | D58: 8 | H58: =L58/24 -> 21.083333 | L58: ='Структура рабочего учебного пла'!U116+'Структура рабочего учебного пла'!U125+'Структура рабочего учебного пла'!V125 -> 506 | O58: ='Структура рабочего учебного пла'!U131+'Структура рабочего учебного пла'!V131 -> 24 | U58: ='Структура рабочего учебного пла'!U117+'Структура рабочего учебного пла'!V126+'Структура рабочего учебного пла'!V129 -> 826 | AA58: 48 | AG58: ='Структура рабочего учебного пла'!G132 -> 36 | AM58: 1 | AP58: 2 | AS58: 43
A59: ИТОГО | D59: =SUM(D55:E58) -> 89 | H59: =SUM(H55:K58) -> 155.58333 | L59: =SUM(L55:N58) -> 3734 | O59: =SUM(O55:T58) -> 156 | U59: =SUM(U55:Z58) -> 1786 | AA59: =SUM(AA55:AF58) -> 48 | AG59: =SUM(AG55:AL58) -> 36 | AM59: =SUM(AM55:AO58) -> 4 | AP59: =SUM(AP55:AR58) -> 32 | AS59: =SUM(AS55:AX58) -> 199

Sheet Структура рабочего учебного пла
C1: Структура рабочего учебного плана
M2: Объем учебного времени | O2: Распределение по курсам и семестрам
A3: Индекс | B3: Наименование модулей / дисциплин | C3: Формы контроля | F3: Объем учебного времени | L3: Самостоятельная работа студента | M3: в том числе | O3: 1 курс | Q3: 2 курс | S3: 3 курс | U3: 4 курс
C4: экзамен | D4: зачет | E4: контрольная работа | F4: Всего кредитов | G4: Всего часов | H4: в том числе | M4: Производственное обучение/ Профессиональная практика | N4: Индивидуальные | O4: Семестры | W4: остаток часов на семестр
H5: теоретические | I5: лабораторно-практические | J5: курсовой проект/работа | K5: самостоятельная работа студента с педагогом | O5: 1 сем | P5: 2 сем | Q5: 3 сем | R5: 4 сем | S5: 5 сем | T5: 6 сем | U5: 7 сем | V5: 8 сем | W5: 1 сем | X5: 2 сем | Y5: 3 сем | Z5: 4 сем | AA5: 5 сем | AB5: 6 сем | AC5: 7 сем | AD5: 8 сем
O6: 17 | P6: 24 | Q6: 17 | R6: 24 | S6: 17 | T6: 24 | U6: 17 | V6: 24 | W6: 17 | X6: 24 | Y6: 17 | Z6: 24 | AA6: 17 | AB6: 24 | AC6: 17 | AD6: 24
A7: 1 | B7: 2 | C7: 3 | D7: 4 | E7: 5 | F7: 6 | G7: 7 | H7: 8 | I7: 9 | J7: 10 | K7: 11 | L7: 12 | M7: 13 | N7: 14 | O7: 15 | P7: 16 | Q7: 17 | R7: 18 | S7: 19 | T7: 20 | U7: 21 | V7: 22 | W7: =600-O133 -> 0 | X7: =840-P133 -> 0 | Y7: =600-Q133 -> 0 | Z7: =840-R133 -> 0 | AA7: =600-S133 -> 0 | AB7: =840-T133 -> 0 | AC7: =600-U133 -> 0 | AD7: =840-V133 -> 0 | AE7: =SUM(W7:AD7) -> 0
A8: ООД 00 | B8: Модуль "Общеобразовательные дисциплины"
A9: ООД 01 | B9: Казахский язык и литература | C9: 2 | D9: 1 | E9: 2 | F9: =G9/24 -> 4 | G9: =SUM(O9:T9) -> 96 | H9: 36 | I9: 48 | K9: 12 | L9: 24 | O9: 40 | P9: 56
A10: ООД 02 | B10: Русский язык | C10: 2 | D10: 1 | E10: 2 | F10: =G10/24 -> 4 | G10: =SUM(O10:T10) -> 96 | H10: 36 | I10: 48 | K10: 12 | L10: 24 | O10: 40 | P10: 56
A11: ООД 03 | B11: Русская литература | D11: 1.2 | E11: 2 | F11: =G11/24 -> 4 | G11: =SUM(O11:T11) -> 96 | H11: 36 | I11: 48 | K11: 12 | L11: 24 | O11: 40 | P11: 56
A12: ООД 04 | B12: Иностранный язык | D12: 1.2 | E12: 2 | F12: =G12/24 -> 4 | G12: =SUM(O12:T12) -> 96 | H12: 36 | I12: 48 | K12: 12 | L12: 24 | O12: 40 | P12: 56
A13: ООД 05 | B13: История Казахстана | C13: 2 | E13: 1 | F13: =G13/24 -> 3 | G13: =SUM(O13:T13) -> 72 | H13: 24 | I13: 36 | K13: 12 | L13: 24 | P13: 72
A14: ООД 06 | B14: Математика | C14: 2 | D14: 1 | E14: 2 | F14: =G14/24 -> 5 | G14: =SUM(O14:T14) -> 120 | H14: 36 | I14: 60 | K14: 24 | L14: 24 | O14: 40 | P14: 80
A15: ООД 07 | B15: Информатика | D15: 1.2 | E15: 2 | F15: =G15/24 -> 3 | G15: =SUM(O15:T15) -> 72 | H15: 24 | I15: 36 | K15: 12 | L15: 24 | O15: 32 | P15: 40
A16: ООД 08 | B16: Начальная военная и технологическая подготовка | D16: 1.2 | E16: 2 | F16: =G16/24 -> 4 | G16: =SUM(O16:T16) -> 96 | H16: 36 | I16: 48 | K16: 12 | L16: 24 | O16: 40 | P16: 56
A17: ООД 09 | B17: Физическая культура | D17: 1.2 | E17: 2 | F17: =G17/24 -> 5 | G17: =SUM(O17:T17) -> 120 | H17: 4 | I17: 92 | K17: 24 | L17: 24 | O17: 40 | P17: 80
A18: ООД 10 | B18: Физика | C18: 2 | D18: 1 | E18: 2 | F18: =G18/24 -> 4 | G18: =SUM(O18:T18) -> 96 | H18: 36 | I18: 48 | K18: 12 | L18: 24 | O18: 40 | P18: 56
A19: ООД 11 | B19: Химия | D19: 1.2 | E19: 2 | F19: =G19/24 -> 4 | G19: =SUM(O19:T19) -> 96 | H19: 36 | I19: 48 | K19: 12 | L19: 24 | O19: 40 | P19: 56
A20: ООД 12 | B20: География | D20: 1 | E20: 1 | F20: =G20/24 -> 3 | G20: =SUM(O20:T20) -> 72 | H20: 24 | I20: 36 | K20: 12 | L20: 24 | O20: 72
A21: ООД 13 | B21: Биология | D21: 1.2 | E21: 2 | F21: =G21/24 -> 3 | G21: =SUM(O21:T21) -> 72 | H21: 24 | I21: 36 | K21: 12 | L21: 24 | O21: 32 | P21: 40
A22: ООД 14 | B22: Всемирная история | D22: 1 | E22: 1 | F22: =G22/24 -> 3 | G22: =SUM(O22:T22) -> 72 | H22: 24 | I22: 36 | K22: 12 | L22: 24 | O22: 72
A23: ООД 15 | B23: Курс "Глобальные компетенции" | D23: 2 | E23: 1 | F23: =G23/24 -> 1 | G23: =SUM(O23:T23) -> 24 | H23: 6 | I23: 12 | K23: 6 | L23: 12 | P23: 24
A24: ООД 16 | B24: Графика и проектирование | D24: 1.2 | E24: 2 | F24: =G24/24 -> 3 | G24: =SUM(O24:T24) -> 72 | H24: 24 | I24: 36 | K24: 12 | L24: 12 | O24: 32 | P24: 40
A25: ПА 01 | B25: Промежуточная аттестация | F25: =G25/24 -> 3 | G25: =SUM(O25:T25) -> 72 | P25: 72
B26: Итого ООД | F26: =SUM(F9:F25) -> 60 | G26: =SUM(G9:G25) -> 1440 | H26: =SUM(H9:H25) -> 442 | I26: =SUM(I9:I25) -> 716 | K26: =SUM(K9:K25) -> 210 | L26: =SUM(L9:L25) -> 360 | O26: =SUM(O9:O25) -> 600 | P26: =SUM(P9:P25) -> 840
A27: ООМ 1 | B27: Развитие и совершенствование физических качеств / Физическая культура
B28: РО 1.1. Укреплять здоровье и соблюдать принципы здорового образа жизни. | D28: 3.4 | F28: =G28/24 -> 2 | G28: =SUM(H28:K28) -> 48 | H28: 4 | I28: 32 | K28: 12 | L28: 12 | Q28: 18 | R28: 30
B29: РО 1.2. Совершенствовать физические качества и психофизиологические способности. | D29: 3.4 | F29: =G29/24 -> 2 | G29: =SUM(H29:K29) -> 48 | H29: 4 | I29: 32 | K29: 12 | L29: 24 | Q29: 18 | R29: 30
B30: Итого теоретического обучения | F30: =G30/24 -> 4 | G30: =SUM(G28:G29) -> 96 | H30: =SUM(H28:H29) -> 8 | I30: =SUM(I28:I29) -> 64 | J30: =SUM(J28:J29) -> 0 | K30: =SUM(K28:K29) -> 24 | Q30: =SUM(Q28:Q29) -> 36 | R30: =SUM(R28:R29) -> 60
B31: Итого практического обучения
B32: Всего за ООМ 1 | F32: =G32/24 -> 4 | G32: =G31+G30 -> 96 | H32: =H31+H30 -> 8 | I32: =I31+I30 -> 64 | J32: =J31+J30 -> 0 | K32: =K31+K30 -> 24 | L32: =SUM(L28:L29) -> 36 | M32: =M31+M30 -> 0 | N32: =N31+N30 -> 0 | O32: =SUM(O28:O31) -> 0 | P32: =SUM(P28:P31) -> 0 | Q32: =SUM(Q28:Q29) -> 36 | R32: =SUM(R28:R29) -> 60 | S32: =S28+S29 -> 0 | T32: =T28+T29 -> 0 | U32: =U28+U29 -> 0 | V32: =V28+V29 -> 0
A33: ООМ 2 | B33: Применение информационно-коммуникационных и цифровых технологий
B34: РО 2.1. Владеть основами информационно-коммуникационных технологий. | D34: 3 | F34: =G34/24 -> 1 | G34: =SUM(H34:K34) -> 24 | H34: 10 | I34: 8 | K34: 6 | L34: 24 | Q34: 24
B35: РО 2.2. Использовать услуги информационно-справочных и интерактивных веб-порталов. | D35: 3 | F35: =G35/24 -> 1 | G35: =SUM(H35:K35) -> 24 | H35: 10 | I35: 8 | K35: 6 | L35: 24 | Q35: 24
B36: РО 2.3. Владеть навыками использования ИИ для обработки данных и оптимизации процессов. | D36: 3 | F36: =G36/24 -> 2 | G36: =SUM(H36:K36) -> 48 | H36: 22 | I36: 20 | K36: 6 | L36: 24 | Q36: 48
B37: Итого теоретического обучения | F37: =G37/24 -> 4 | G37: =H37+I37+J37+K37 -> 96 | H37: =SUM(H34:H36) -> 42 | I37: =SUM(I34:I36) -> 36 | J37: =SUM(J34:J36) -> 0 | K37: =SUM(K34:K36) -> 18 | Q37: =SUM(Q34:Q36) -> 96
B38: Итого практического обучения
B39: Всего за ООМ 2 | D39: 3 | F39: =G39/24 -> 4 | G39: =G38+G37 -> 96 | H39: =H38+H37 -> 42 | I39: =I38+I37 -> 36 | J39: =J38+J37 -> 0 | K39: =K38+K37 -> 18 | L39: =SUM(L34:L36) -> 72 | M39: =M38+M37 -> 0 | N39: =N38+N37 -> 0 | O39: =O38+O37 -> 0 | P39: =P38+P37 -> 0 | Q39: =Q38+Q37 -> 96 | R39: =R38+R37 -> 0 | S39: =S38+S37 -> 0 | T39: =T38+T37 -> 0 | ... V39: =V38+V37 -> 0
A40: ООМ 3 | B40: Применение базовых знаний экономики и основ предпринимательства / Основы экономики
...
